Workbook

Sheet INSTRUCTIONS | تعليمات
A1: شركة كيان للابتكار وريادة الأعمال وبيئات العمل ذ.م.م
A2: Kayan Innovation, Entrepreneurship & Work Environments LLC
A3: MEMBER MANAGEMENT SYSTEM | نظام إدارة الأعضاء
A4: KAY-OPS-MMS-001 | v1.0 | Effective: 1 May 2026 | Owner: Workspace Lead | Approved: CEO
B6: Document ID | رقم الوثيقة | C6: KAY-OPS-MMS-001
B7: Version | الإصدار | C7: v1.0
B8: Effective Date | تاريخ السريان | C8: 1 May 2026
B9: Classification | التصنيف | C9: INTERNAL — OPERATIONAL
B10: Owner | المسؤول | C10: Workspace Lead | مدير مساحة العمل
B11: Daily Updated By | يُحدّث يومياً بواسطة | C11: Reception Staff / Workspace Lead
B12: Reviewed By | يُراجع بواسطة | C12: CEO — Weekly
B13: Backup Frequency | تكرار النسخ الاحتياطي | C13: Daily (Google Drive auto-sync)
B14: Exchange Rate | سعر الصرف | C14: dated Aden market rate (LOCKED)
B15: Cross-References | المراجع المتقاطعة | C15: KAY-OPS-CHK-001, KAY-OPS-HBK-001, KAY-LEG-WMA-001, KAY-FRM-PACK-001, KAY-CON-012
B17: ⚠ COUNSEL VALIDATION: Items marked ⚖ require legal review per KAY-LEG-011 Phase 2
B19: SYSTEM OVERVIEW | نظرة عامة على النظام
B20: Tab 2: Member Registry سجل الأعضاء | C20: Master database of every member. One row per member. Tracks ID, plan, dates, payment, emergency contact, consents. NEVER delete rows — mark as 'Expired' or 'Terminated'.
B21: Tab 3: Daily Check-In Log سجل تسجيل الدخول اليومي | C21: Every person entering Kayan Hub signs in and out. Security (who is in the building), utilization (occupancy KPIs), community (greet everyone by name).
B22: Tab 4: Day Pass Sales Log سجل مبيعات التصاريح اليومية | C22: Every day pass sold with name, phone, amount, receipt number. Links to cash reconciliation form KAY-OPS-CHK-001 Part 5B.
B23: Tab 5: Renewal Tracker متتبع التجديد | C23: 7-day warning before expiry. Follow-up call/WhatsApp. Track who renewed, who churned, and why.
B24: Tab 6: Conversion Funnel قمع التحويل | C24: Day pass visitors who become members. Visit → Return Visit → Flex → Unlimited → Dedicated. If 100 day passes but 0 conversions = value proposition problem.
B25: Tab 7: Dashboard لوحة المؤشرات | C25: Real-time KPIs: active members, occupancy rate, revenue by plan, conversion rate, churn rate. Auto-calculated from other tabs.
B26: Tab 8: Pricing Reference مرجع الأسعار | C26: Locked pricing card from KAY-LEG-WMA-001. USD + YER. Discount authority matrix from DOA.
B27: Tab 9: Risk & Accountability المخاطر والمساءلة | C27: Data protection risks, GDPR-equivalent for Yemen, member data handling protocols, accountability matrix.
B29: OPERATIONAL RULES | القواعد التشغيلية
B30: RULE 1: Every person through the door gets logged — NO EXCEPTIONS. Members, guests, day pass, staff, visitors.
B31: RULE 2: NEVER delete a member record. Change Status to 'Expired', 'Terminated', or 'Suspended'. Audit trail is sacred.
B32: RULE 3: Day Pass cash must reconcile with KAY-OPS-CHK-001 Part 5B revenue table EVERY DAY. Variance = incident report.
B33: RULE 4: Renewal follow-up starts 7 days before expiry. WhatsApp + call. Log every attempt in Renewal Tracker.
B34: RULE 5: Member data is CONFIDENTIAL. No sharing of member contact details, no screenshots of this file to non-staff.
B35: RULE 6: ⚖ COUNSEL: Member personal data handling must comply with KAY-DAT-001 Data Protection Policy. Validate with counsel.
B36: RULE 7: Backup this file to Google Drive EVERY DAY before closing. Workspace Lead confirms in WhatsApp to CEO.
B37: RULE 8: CEO reviews Dashboard tab every Monday at staff meeting. Workspace Lead presents Week's metrics.
B38: RULE 9: Member ID format: KH-YYYY-NNNN (KH = Kayan Hub, YYYY = year, NNNN = sequential). First member = KH-2026-0001.
B39: RULE 10: ⚖ COUNSEL: Photo consent and CCTV consent must be collected per KAY-COM-PDP-001. Validate with counsel.

Sheet MEMBER REGISTRY | سجل الأعضاء
A1: MEMBER REGISTRY | سجل الأعضاء
A2: KAY-OPS-MMS-001 Tab 2 | Kayan Hub — Khormaksar, Aden | Every person = one row. NEVER delete rows.
A3: ⚠ CONFIDENTIAL DATA — DO NOT SHARE. Member data protected under KAY-DAT-001 & KAY-COM-PDP-001. ⚖ COUNSEL VALIDATION REQUIRED.
A5: Member ID رقم العضوية | B5: Full Name (EN) الاسم الكامل (إنجليزي) | C5: Full Name (AR) الاسم الكامل (عربي) | D5: National ID رقم الهوية | E5: Phone الهاتف | F5: Email البريد الإلكتروني | G5: Organization المنظمة | H5: Membership Plan نوع العضوية | I5: Price USD السعر دولار | J5: Price YER السعر ريال | K5: Start Date تاريخ البدء | L5: Expiry Date تاريخ الانتهاء | M5: Status الحالة | N5: Payment Method طريقة الدفع | O5: Payment Status حالة الدفع | P5: Receipt # رقم الإيصال | Q5: Emergency Contact Name اسم جهة اتصال الطوارئ | R5: Emergency Phone هاتف الطوارئ | S5: Emergency Relation العلاقة | T5: Photo Consent موافقة التصوير | U5: CCTV Consent موافقة الكاميرات | V5: Handbook Signed الدليل موقع | W5: Agreement Signed الاتفاقية موقعة | X5: Referred By مُحال بواسطة | Y5: Source المصدر | Z5: Special Needs احتياجات خاصة | AA5: Locker # رقم الخزانة | AB5: Notes ملاحظات | AC5: Registered By سُجّل بواسطة | AD5: Registration Date تاريخ التسجيل
A6: KAY-M001 | B6: Nasser Al-Awlaki | C6: ناصر العولقي | D6: VERIFIED | E6: 770123456 | F6: nasser@email.com | G6: Freelancer | H6: Dedicated Desk | I6: 82 | J6: 139400 | K6: 2026-06-01 | L6: 2026-06-30 | M6: Active | N6: Cash | O6: Badr | P6: RCT-0001 | Q6: Fatima Mohammed | R6: +967-777-654321 | S6: Sister | T6: Yes | U6: Yes | V6: Yes | W6: Yes | Y6: Walk-in | AB6: Welcome member #1! | AC6: Workspace Lead | AD6: 2026-05-01
A7: KAY-M002 | B7: Fatima Al-Zubairi | C7: فاطمة الزبيري | D7: VERIFIED | E7: 773456789 | F7: fatima@email.com | G7: NGO Consultant | H7: Flex Monthly | I7: 45 | J7: 76500 | K7: 2026-06-01 | L7: 2026-06-30 | M7: Active | N7: Cash | O7: Badr
A8: KAY-M003 | B8: Omar Saeed Bin Laden | C8: عمر سعيد بن لادن | D8: VERIFIED | E8: 771234567 | F8: omar.s@email.com | G8: Architect | H8: Dedicated Desk | I8: 82 | J8: 139400 | K8: 2026-06-01 | L8: 2026-06-30 | M8: Active | N8: Cash | O8: Badr
A9: KAY-M004 | B9: Aisha Mohammed Qassem | C9: عائشة محمد قاسم | D9: VERIFIED | E9: 775678901 | F9: aisha.q@email.com | G9: Translation | H9: Flex Monthly | I9: 45 | J9: 76500 | K9: 2026-06-01 | L9: 2026-06-30 | M9: Active | N9: Cash | O9: Badr
A10: KAY-M005 | B10: Khaled Al-Jabri | C10: خالد الجابري | D10: VERIFIED | E10: 772345678 | F10: khaled.j@email.com | G10: IT Consultant | H10: Dedicated Desk | I10: 82 | J10: 139400 | K10: 2026-06-05 | L10: 2026-07-04 | M10: Active | N10: Cash | O10: Badr
A11: KAY-M006 | B11: Samira Ahmed Hassan | C11: سميرة أحمد حسن | D11: VERIFIED | E11: 774567890 | F11: samira@email.com | G11: HR Specialist | H11: Flex Monthly | I11: 45 | J11: 76500 | K11: 2026-06-08 | L11: 2026-07-07 | M11: Active | N11: Cash | O11: Badr
A12: KAY-M007 | B12: Waleed Nasser | C12: وليد ناصر | D12: VERIFIED | E12: 776789012 | F12: waleed.n@email.com | G12: Graphic Designer | H12: Flex Monthly | I12: 45 | J12: 76500 | K12: 2026-06-10 | L12: 2026-07-09 | M12: Active | N12: Cash | O12: Badr
A13: KAY-M008 | B13: Huda Al-Salahi | C13: هدى الصلاحي | D13: VERIFIED | E13: 778901234 | F13: huda.s@email.com | G13: Social Media Mgr | H13: Day Pass Conversion | I13: 0 | J13: 0 | K13: 2026-06-15 | L13: 2026-07-14 | M13: Active | N13: Cash | O13: Badr
I14: =IF(H14="Day Pass",5,IF(H14="Half-Day/Evening",3,IF(H14="Monthly Flex (8 days)",30,IF(H14="Monthly Unlimited",60,IF(H14="Dedicated Desk",90,""))))) | J14: =IF(I14="","",I14*1700)
I15: =IF(H15="Day Pass",5,IF(H15="Half-Day/Evening",3,IF(H15="Monthly Flex (8 days)",30,IF(H15="Monthly Unlimited",60,IF(H15="Dedicated Desk",90,""))))) | J15: =IF(I15="","",I15*1700)
I16: =IF(H16="Day Pass",5,IF(H16="Half-Day/Evening",3,IF(H16="Monthly Flex (8 days)",30,IF(H16="Monthly Unlimited",60,IF(H16="Dedicated Desk",90,""))))) | J16: =IF(I16="","",I16*1700)
I17: =IF(H17="Day Pass",5,IF(H17="Half-Day/Evening",3,IF(H17="Monthly Flex (8 days)",30,IF(H17="Monthly Unlimited",60,IF(H17="Dedicated Desk",90,""))))) | J17: =IF(I17="","",I17*1700)
I18: =IF(H18="Day Pass",5,IF(H18="Half-Day/Evening",3,IF(H18="Monthly Flex (8 days)",30,IF(H18="Monthly Unlimited",60,IF(H18="Dedicated Desk",90,""))))) | J18: =IF(I18="","",I18*1700)
I19: =IF(H19="Day Pass",5,IF(H19="Half-Day/Evening",3,IF(H19="Monthly Flex (8 days)",30,IF(H19="Monthly Unlimited",60,IF(H19="Dedicated Desk",90,""))))) | J19: =IF(I19="","",I19*1700)
I20: =IF(H20="Day Pass",5,IF(H20="Half-Day/Evening",3,IF(H20="Monthly Flex (8 days)",30,IF(H20="Monthly Unlimited",60,IF(H20="Dedicated Desk",90,""))))) | J20: =IF(I20="","",I20*1700)
I21: =IF(H21="Day Pass",5,IF(H21="Half-Day/Evening",3,IF(H21="Monthly Flex (8 days)",30,IF(H21="Monthly Unlimited",60,IF(H21="Dedicated Desk",90,""))))) | J21: =IF(I21="","",I21*1700)
I22: =IF(H22="Day Pass",5,IF(H22="Half-Day/Evening",3,IF(H22="Monthly Flex (8 days)",30,IF(H22="Monthly Unlimited",60,IF(H22="Dedicated Desk",90,""))))) | J22: =IF(I22="","",I22*1700)
I23: =IF(H23="Day Pass",5,IF(H23="Half-Day/Evening",3,IF(H23="Monthly Flex (8 days)",30,IF(H23="Monthly Unlimited",60,IF(H23="Dedicated Desk",90,""))))) | J23: =IF(I23="","",I23*1700)
I24: =IF(H24="Day Pass",5,IF(H24="Half-Day/Evening",3,IF(H24="Monthly Flex (8 days)",30,IF(H24="Monthly Unlimited",60,IF(H24="Dedicated Desk",90,""))))) | J24: =IF(I24="","",I24*1700)
I25: =IF(H25="Day Pass",5,IF(H25="Half-Day/Evening",3,IF(H25="Monthly Flex (8 days)",30,IF(H25="Monthly Unlimited",60,IF(H25="Dedicated Desk",90,""))))) | J25: =IF(I25="","",I25*1700)
... I505: =IF(H505="Day Pass",5,IF(H505="Half-Day/Evening",3,IF(H505="Monthly Flex (8 days)",30,IF(H505="Monthly Unlimited",60,IF(H505="Dedicated Desk",90,""))))) | J505: =IF(I505="","",I505*1700)

Sheet CHECK-IN LOG | سجل الدخول
A1: DAILY CHECK-IN LOG | سجل تسجيل الدخول اليومي | KAY-OPS-MMS-001 Tab 3
A2: PURPOSE: Security (who is in the building at any time) + Utilization (occupancy KPIs) + Community (greet everyone by name)
A3: ⚠ LOG EVERY PERSON. No exceptions. Guests must show valid ID at reception. Max 2 guests per member. >2 hours or >2 guests = Day Pass required.
A4: Date التاريخ | B4: Member ID رقم العضوية | C4: Name الاسم | D4: Plan Type نوع العضوية | E4: Check-In Time وقت الدخول | F4: Check-Out Time وقت الخروج | G4: Hours الساعات | H4: Zone Used المنطقة | I4: Guest? ضيف؟ | J4: Guest Name (if yes) اسم الضيف | K4: Guest ID Logged? هوية الضيف مسجلة؟ | L4: Wi-Fi Voucher # رقم قسيمة الواي فاي | M4: Notes ملاحظات | N4: Logged By سُجّل بواسطة
A5: 2026-06-01 | B5: KAY-M001 | C5: Nasser Al-Awlaki | D5: Dedicated Desk | E5: 09:00 | F5: 16:00 | G5: =7 | H5: Dedicated Desk | I5: No | L5: WF-003
A6: 2026-06-01 | B6: KAY-M005 | C6: Khaled Al-Jabri | D6: Dedicated Desk | E6: 08:00 | F6: 14:00 | G6: =6 | H6: Meeting Room | I6: No | L6: WF-003
A7: 2026-06-01 | B7: KAY-M006 | C7: Samira Ahmed Hassan | D7: Flex Monthly | E7: 08:30 | F7: 18:00 | G7: =10 | H7: Dedicated Desk | I7: No | L7: WF-003
A8: 2026-06-01 | B8: KAY-M004 | C8: Aisha Mohammed Qassem | D8: Flex Monthly | E8: 10:00 | F8: 18:00 | G8: =8 | H8: Dedicated Desk | I8: No | L8: WF-002
A9: 2026-06-02 | B9: KAY-M003 | C9: Omar Saeed Bin Laden | D9: Dedicated Desk | E9: 08:00 | F9: 18:00 | G9: =10 | H9: Dedicated Desk | I9: No | L9: WF-002
A10: 2026-06-02 | B10: KAY-M006 | C10: Samira Ahmed Hassan | D10: Flex Monthly | E10: 09:30 | F10: 16:00 | G10: =7 | H10: Open Space | I10: No | L10: WF-001
A11: 2026-06-02 | B11: KAY-M005 | C11: Khaled Al-Jabri | D11: Dedicated Desk | E11: 10:00 | F11: 16:00 | G11: =6 | H11: Dedicated Desk | I11: No | L11: WF-002
A12: 2026-06-02 | B12: KAY-M004 | C12: Aisha Mohammed Qassem | D12: Flex Monthly | E12: 08:30 | F12: 15:00 | G12: =7 | H12: Dedicated Desk | I12: No | L12: WF-001
A13: 2026-06-02 | B13: KAY-M002 | C13: Fatima Al-Zubairi | D13: Flex Monthly | E13: 08:00 | F13: 16:00 | G13: =8 | H13: Dedicated Desk | I13: No | L13: WF-003
A14: 2026-06-02 | B14: KAY-M007 | C14: Waleed Nasser | D14: Flex Monthly | E14: 10:00 | F14: 15:00 | G14: =5 | H14: Meeting Room | I14: No | L14: WF-002
A15: 2026-06-03 | B15: KAY-M003 | C15: Omar Saeed Bin Laden | D15: Dedicated Desk | E15: 09:30 | F15: 18:00 | G15: =9 | H15: Open Space | I15: No | L15: WF-002
A16: 2026-06-03 | B16: KAY-M002 | C16: Fatima Al-Zubairi | D16: Flex Monthly | E16: 08:30 | F16: 15:00 | G16: =7 | H16: Meeting Room | I16: No | L16: WF-001
A17: 2026-06-03 | B17: KAY-M001 | C17: Nasser Al-Awlaki | D17: Dedicated Desk | E17: 09:00 | F17: 15:00 | G17: =6 | H17: Open Space | I17: No | L17: WF-002
A18: 2026-06-04 | B18: KAY-M004 | C18: Aisha Mohammed Qassem | D18: Flex Monthly | E18: 10:00 | F18: 15:00 | G18: =5 | H18: Open Space | I18: No | L18: WF-002
A19: 2026-06-04 | B19: KAY-M007 | C19: Waleed Nasser | D19: Flex Monthly | E19: 08:30 | F19: 17:00 | G19: =9 | H19: Meeting Room | I19: No | L19: WF-003
A20: 2026-06-04 | B20: KAY-M002 | C20: Fatima Al-Zubairi | D20: Flex Monthly | E20: 10:00 | F20: 15:00 | G20: =5 | H20: Meeting Room | I20: No | L20: WF-003
A21: 2026-06-04 | B21: KAY-M005 | C21: Khaled Al-Jabri | D21: Dedicated Desk | E21: 10:00 | F21: 17:00 | G21: =7 | H21: Open Space | I21: No | L21: WF-003
A22: 2026-06-04 | B22: KAY-M001 | C22: Nasser Al-Awlaki | D22: Dedicated Desk | E22: 08:30 | F22: 16:00 | G22: =8 | H22: Dedicated Desk | I22: No | L22: WF-002
A23: 2026-06-04 | B23: KAY-M008 | C23: Huda Al-Salahi | D23: Day Pass Conversion | E23: 08:00 | F23: 17:00 | G23: =9 | H23: Dedicated Desk | I23: No | L23: WF-001
A24: 2026-06-06 | B24: KAY-M003 | C24: Omar Saeed Bin Laden | D24: Dedicated Desk | E24: 08:00 | F24: 15:00 | G24: =7 | H24: Dedicated Desk | I24: No | L24: WF-003
A25: 2026-06-06 | B25: KAY-M001 | C25: Nasser Al-Awlaki | D25: Dedicated Desk | E25: 10:00 | F25: 18:00 | G25: =8 | H25: Dedicated Desk | I25: No | L25: WF-002
A26: 2026-06-06 | B26: KAY-M006 | C26: Samira Ahmed Hassan | D26: Flex Monthly | E26: 08:30 | F26: 18:00 | G26: =10 | H26: Dedicated Desk | I26: No | L26: WF-002
A27: 2026-06-06 | B27: KAY-M007 | C27: Waleed Nasser | D27: Flex Monthly | E27: 08:00 | F27: 18:00 | G27: =10 | H27: Meeting Room | I27: No | L27: WF-001
A28: 2026-06-06 | B28: KAY-M004 | C28: Aisha Mohammed Qassem | D28: Flex Monthly | E28: 09:00 | F28: 16:00 | G28: =7 | H28: Open Space | I28: No | L28: WF-002
A29: 2026-06-07 | B29: KAY-M003 | C29: Omar Saeed Bin Laden | D29: Dedicated Desk | E29: 09:00 | F29: 14:00 | G29: =5 | H29: Open Space | I29: No | L29: WF-001
A30: 2026-06-07 | B30: KAY-M002 | C30: Fatima Al-Zubairi | D30: Flex Monthly | E30: 08:30 | F30: 15:00 | G30: =7 | H30: Dedicated Desk | I30: No | L30: WF-002
A31: 2026-06-07 | B31: KAY-M001 | C31: Nasser Al-Awlaki | D31: Dedicated Desk | E31: 08:30 | F31: 14:00 | G31: =6 | H31: Open Space | I31: No | L31: WF-003
A32: 2026-06-08 | B32: KAY-M003 | C32: Omar Saeed Bin Laden | D32: Dedicated Desk | E32: 10:00 | F32: 17:00 | G32: =7 | H32: Meeting Room | I32: No | L32: WF-003
A33: 2026-06-08 | B33: KAY-M001 | C33: Nasser Al-Awlaki | D33: Dedicated Desk | E33: 08:00 | F33: 17:00 | G33: =9 | H33: Dedicated Desk | I33: No | L33: WF-003
A34: 2026-06-08 | B34: KAY-M004 | C34: Aisha Mohammed Qassem | D34: Flex Monthly | E34: 10:00 | F34: 15:00 | G34: =5 | H34: Open Space | I34: No | L34: WF-001
A35: 2026-06-08 | B35: KAY-M006 | C35: Samira Ahmed Hassan | D35: Flex Monthly | E35: 10:00 | F35: 15:00 | G35: =5 | H35: Open Space | I35: No | L35: WF-003
A36: 2026-06-09 | B36: KAY-M003 | C36: Omar Saeed Bin Laden | D36: Dedicated Desk | E36: 08:00 | F36: 18:00 | G36: =10 | H36: Meeting Room | I36: No | L36: WF-003
A37: 2026-06-09 | B37: KAY-M001 | C37: Nasser Al-Awlaki | D37: Dedicated Desk | E37: 09:00 | F37: 16:00 | G37: =7 | H37: Meeting Room | I37: No | L37: WF-001
A38: 2026-06-09 | B38: KAY-M004 | C38: Aisha Mohammed Qassem | D38: Flex Monthly | E38: 09:00 | F38: 17:00 | G38: =8 | H38: Open Space | I38: No | L38: WF-001
A39: 2026-06-10 | B39: KAY-M004 | C39: Aisha Mohammed Qassem | D39: Flex Monthly | E39: 09:00 | F39: 17:00 | G39: =8 | H39: Open Space | I39: No | L39: WF-001
A40: 2026-06-10 | B40: KAY-M002 | C40: Fatima Al-Zubairi | D40: Flex Monthly | E40: 10:00 | F40: 16:00 | G40: =6 | H40: Open Space | I40: No | L40: WF-003
...

Sheet DAY PASS LOG | سجل التصاريح
A1: DAY PASS SALES LOG | سجل مبيعات التصاريح اليومية | KAY-OPS-MMS-001 Tab 4
A2: ⚠ CASH MUST RECONCILE with KAY-OPS-CHK-001 Part 5B 'Workspace — Day Passes' line. Daily total from this log = revenue reported on closing form. Any mismatch = incident report.
A3: PURPOSE: Revenue tracking + Conversion pipeline source data. Columns M-P feed the Conversion Funnel tab. Every day pass buyer is a potential member.
A4: Date التاريخ | B4: # رقم | C4: Visitor Full Name اسم الزائر الكامل | D4: Visitor Name (AR) الاسم (عربي) | E4: Phone الهاتف | F4: National ID رقم الهوية | G4: Pass Type نوع التصريح | H4: Amount USD دولار | I4: Amount YER ريال | J4: Payment Method طريقة الدفع | K4: Receipt # رقم الإيصال | L4: Referred By مُحال بواسطة | M4: Return Visit? زيارة عائد؟ | N4: Offered Flex? عُرض عليه فليكس؟ | O4: Interest Level مستوى الاهتمام | P4: Follow-up Action إجراء المتابعة | Q4: Logged By سُجّل بواسطة
A5: 2026-06-01 | B5: 1 | C5: Saleh Al-Yafi | D5: صالح اليافعي | E5: 777111222 | F5: LOGGED | G5: Day Pass (FREE) | H5: 0 | I5: 0 | J5: N/A (Free) | K5: N/A | L5: Walk-in | M5: No
A6: 2026-06-03 | B6: 2 | C6: Rania Mohammed | D6: رانيا محمد | E6: 773222333 | F6: LOGGED | G6: Day Pass (FREE) | H6: 0 | I6: 0 | J6: N/A (Free) | K6: N/A | L6: Facebook | M6: No
A7: 2026-06-05 | B7: 3 | C7: Ammar Bin Sunker | D7: عمار بن سنكر | E7: 771333444 | F7: LOGGED | G7: Day Pass (FREE) | H7: 0 | I7: 0 | J7: N/A (Free) | K7: N/A | L7: Referral | M7: No
A8: 2026-06-07 | B8: 4 | C8: Lina Al-Habshi | D8: لينا الحبشي | E8: 775444555 | F8: LOGGED | G8: Day Pass (FREE) | H8: 0 | I8: 0 | J8: N/A (Free) | K8: N/A | L8: Walk-in | M8: No
A9: 2026-06-09 | B9: 5 | C9: Mustafa Omer | D9: مصطفى عمر | E9: 772555666 | F9: LOGGED | G9: Day Pass (FREE) | H9: 0 | I9: 0 | J9: N/A (Free) | K9: N/A | L9: LinkedIn | M9: No
A10: 2026-06-11 | B10: 6 | C10: Dina Saeed | D10: دينا سعيد | E10: 774666777 | F10: LOGGED | G10: Day Pass (FREE) | H10: 0 | I10: 0 | J10: N/A (Free) | K10: N/A | L10: Walk-in | M10: Yes
A11: 2026-06-13 | B11: 7 | C11: Faisal Al-Dhubhani | D11: فيصل الذبحاني | E11: 776777888 | F11: LOGGED | G11: Day Pass (FREE) | H11: 0 | I11: 0 | J11: N/A (Free) | K11: N/A | L11: Referral | M11: Yes
A12: 2026-06-15 | B12: 8 | C12: Jana Abdullah | D12: جنى عبدالله | E12: 778888999 | F12: LOGGED | G12: Day Pass (FREE) | H12: 0 | I12: 0 | J12: N/A (Free) | K12: N/A | L12: Facebook | M12: Yes
H13: =IF(G13="Day Pass ($5)",5,IF(G13="Half-Day ($3)",3,"")) | I13: =IF(H13="","",H13*1700)
H14: =IF(G14="Day Pass ($5)",5,IF(G14="Half-Day ($3)",3,"")) | I14: =IF(H14="","",H14*1700)
H15: =IF(G15="Day Pass ($5)",5,IF(G15="Half-Day ($3)",3,"")) | I15: =IF(H15="","",H15*1700)
H16: =IF(G16="Day Pass ($5)",5,IF(G16="Half-Day ($3)",3,"")) | I16: =IF(H16="","",H16*1700)
H17: =IF(G17="Day Pass ($5)",5,IF(G17="Half-Day ($3)",3,"")) | I17: =IF(H17="","",H17*1700)
H18: =IF(G18="Day Pass ($5)",5,IF(G18="Half-Day ($3)",3,"")) | I18: =IF(H18="","",H18*1700)
H19: =IF(G19="Day Pass ($5)",5,IF(G19="Half-Day ($3)",3,"")) | I19: =IF(H19="","",H19*1700)
H20: =IF(G20="Day Pass ($5)",5,IF(G20="Half-Day ($3)",3,"")) | I20: =IF(H20="","",H20*1700)
H21: =IF(G21="Day Pass ($5)",5,IF(G21="Half-Day ($3)",3,"")) | I21: =IF(H21="","",H21*1700)
H22: =IF(G22="Day Pass ($5)",5,IF(G22="Half-Day ($3)",3,"")) | I22: =IF(H22="","",H22*1700)
H23: =IF(G23="Day Pass ($5)",5,IF(G23="Half-Day ($3)",3,"")) | I23: =IF(H23="","",H23*1700)
H24: =IF(G24="Day Pass ($5)",5,IF(G24="Half-Day ($3)",3,"")) | I24: =IF(H24="","",H24*1700)
... H1004: =IF(G1004="Day Pass ($5)",5,IF(G1004="Half-Day ($3)",3,"")) | I1004: =IF(H1004="","",H1004*1700)

Sheet RENEWAL TRACKER | متتبع التجديد
A1: MEMBERSHIP RENEWAL TRACKER | متتبع تجديد العضوية | KAY-OPS-MMS-001 Tab 5
A2: ⚠ Start contact 7 DAYS before expiry. Auto-renew per KAY-LEG-WMA-001 Art.2.2 unless 5-day written notice. Log EVERY contact attempt — churn analysis depends on this.
A3: Column E auto-calculates days to expiry. Red = overdue. Amber = ≤7 days. Green = >7 days. Target: 80% renewal rate by M6.
A4: Member ID رقم العضوية | B4: Member Name اسم العضو | C4: Plan الخطة | D4: Expiry Date تاريخ الانتهاء | E4: Days Until Expiry أيام للانتهاء | F4: Alert Status حالة التنبيه | G4: 1st Contact Date تاريخ أول اتصال | H4: 1st Contact Method طريقة الاتصال | I4: 2nd Contact Date تاريخ ثاني اتصال | J4: Member Response رد العضو | K4: Renewal Decision قرار التجديد | L4: New Expiry Date تاريخ الانتهاء الجديد | M4: Payment Received? هل تم الدفع؟ | N4: If Churned: Reason إذا غادر: السبب | O4: Notes / Follow-up ملاحظات / متابعة | P4: Handled By تم بواسطة
E5: =IF(D5="","",D5-TODAY()) | F5: =IF(E5="","",IF(E5<0,"OVERDUE",IF(E5<=3,"URGENT",IF(E5<=7,"CONTACT NOW","OK"))))
E6: =IF(D6="","",D6-TODAY()) | F6: =IF(E6="","",IF(E6<0,"OVERDUE",IF(E6<=3,"URGENT",IF(E6<=7,"CONTACT NOW","OK"))))
E7: =IF(D7="","",D7-TODAY()) | F7: =IF(E7="","",IF(E7<0,"OVERDUE",IF(E7<=3,"URGENT",IF(E7<=7,"CONTACT NOW","OK"))))
E8: =IF(D8="","",D8-TODAY()) | F8: =IF(E8="","",IF(E8<0,"OVERDUE",IF(E8<=3,"URGENT",IF(E8<=7,"CONTACT NOW","OK"))))
E9: =IF(D9="","",D9-TODAY()) | F9: =IF(E9="","",IF(E9<0,"OVERDUE",IF(E9<=3,"URGENT",IF(E9<=7,"CONTACT NOW","OK"))))
E10: =IF(D10="","",D10-TODAY()) | F10: =IF(E10="","",IF(E10<0,"OVERDUE",IF(E10<=3,"URGENT",IF(E10<=7,"CONTACT NOW","OK"))))
E11: =IF(D11="","",D11-TODAY()) | F11: =IF(E11="","",IF(E11<0,"OVERDUE",IF(E11<=3,"URGENT",IF(E11<=7,"CONTACT NOW","OK"))))
E12: =IF(D12="","",D12-TODAY()) | F12: =IF(E12="","",IF(E12<0,"OVERDUE",IF(E12<=3,"URGENT",IF(E12<=7,"CONTACT NOW","OK"))))
E13: =IF(D13="","",D13-TODAY()) | F13: =IF(E13="","",IF(E13<0,"OVERDUE",IF(E13<=3,"URGENT",IF(E13<=7,"CONTACT NOW","OK"))))
E14: =IF(D14="","",D14-TODAY()) | F14: =IF(E14="","",IF(E14<0,"OVERDUE",IF(E14<=3,"URGENT",IF(E14<=7,"CONTACT NOW","OK"))))
E15: =IF(D15="","",D15-TODAY()) | F15: =IF(E15="","",IF(E15<0,"OVERDUE",IF(E15<=3,"URGENT",IF(E15<=7,"CONTACT NOW","OK"))))
E16: =IF(D16="","",D16-TODAY()) | F16: =IF(E16="","",IF(E16<0,"OVERDUE",IF(E16<=3,"URGENT",IF(E16<=7,"CONTACT NOW","OK"))))
... E504: =IF(D504="","",D504-TODAY()) | F504: =IF(E504="","",IF(E504<0,"OVERDUE",IF(E504<=3,"URGENT",IF(E504<=7,"CONTACT NOW","OK"))))

Sheet CONVERSION FUNNEL | قمع التحويل
A1: CONVERSION FUNNEL | قمع التحويل: من زائر إلى عضو | KAY-OPS-MMS-001 Tab 6
A2: Every day pass buyer is tracked here. Target: 15% conversion rate (day pass → paid membership) by M6. If 100 day passes & 0 conversions = VALUE PROPOSITION PROBLEM.
A3: Stage Flow: Day Pass Visit → Return Visit → Considering (asked about plans) → Flex Trial → Unlimited/Dedicated. Track the BARRIERS — that's where we improve.
A4: Visitor Name اسم الزائر | B4: Phone الهاتف | C4: Source المصدر | D4: 1st Visit Date تاريخ الزيارة الأولى | E4: 2nd Visit Date الزيارة الثانية | F4: 3rd Visit Date الزيارة الثالثة | G4: Total Visits إجمالي الزيارات | H4: Current Stage المرحلة الحالية | I4: Plan Interested In الخطة المهتم بها | J4: Barrier to Conversion عائق التحويل | K4: Follow-up Date تاريخ المتابعة | L4: Follow-up Action إجراء المتابعة | M4: Converted? هل تحوّل؟ | N4: Converted to Plan تحوّل إلى خطة | O4: Conversion Date تاريخ التحويل | P4: Days to Convert أيام للتحويل | Q4: Assigned To مسؤول المتابعة
G5: =COUNTA(D5:F5) | P5: =IF(AND(O5<>"",D5<>""),O5-D5,"")
G6: =COUNTA(D6:F6) | P6: =IF(AND(O6<>"",D6<>""),O6-D6,"")
G7: =COUNTA(D7:F7) | P7: =IF(AND(O7<>"",D7<>""),O7-D7,"")
G8: =COUNTA(D8:F8) | P8: =IF(AND(O8<>"",D8<>""),O8-D8,"")
G9: =COUNTA(D9:F9) | P9: =IF(AND(O9<>"",D9<>""),O9-D9,"")
G10: =COUNTA(D10:F10) | P10: =IF(AND(O10<>"",D10<>""),O10-D10,"")
G11: =COUNTA(D11:F11) | P11: =IF(AND(O11<>"",D11<>""),O11-D11,"")
G12: =COUNTA(D12:F12) | P12: =IF(AND(O12<>"",D12<>""),O12-D12,"")
G13: =COUNTA(D13:F13) | P13: =IF(AND(O13<>"",D13<>""),O13-D13,"")
G14: =COUNTA(D14:F14) | P14: =IF(AND(O14<>"",D14<>""),O14-D14,"")
G15: =COUNTA(D15:F15) | P15: =IF(AND(O15<>"",D15<>""),O15-D15,"")
G16: =COUNTA(D16:F16) | P16: =IF(AND(O16<>"",D16<>""),O16-D16,"")
... G504: =COUNTA(D504:F504) | P504: =IF(AND(O504<>"",D504<>""),O504-D504,"")

Sheet DASHBOARD | لوحة المؤشرات
A1: KAYAN HUB — MEMBER MANAGEMENT DASHBOARD | لوحة مؤشرات إدارة الأعضاء
A2: Auto-calculated from Registry, Check-In, Day Pass, and Renewal tabs. Reviewed by CEO every Monday.
B4: MEMBERSHIP SUMMARY | ملخص العضوية
B5: Total Active Members | إجمالي الأعضاء النشطين | C5: =COUNTIF('MEMBER REGISTRY | سجل الأعضاء'!M6:M505,"Active")
B6: Day Pass (active) | تصريح يومي | C6: =COUNTIFS('MEMBER REGISTRY | سجل الأعضاء'!M6:M505,"Active",'MEMBER REGISTRY | سجل الأعضاء'!H6:H505,"Day Pass")
B7: Monthly Flex (active) | شهري مرن | C7: =COUNTIFS('MEMBER REGISTRY | سجل الأعضاء'!M6:M505,"Active",'MEMBER REGISTRY | سجل الأعضاء'!H6:H505,"Monthly Flex (8 days)")
B8: Monthly Unlimited (active) | شهري غير محدود | C8: =COUNTIFS('MEMBER REGISTRY | سجل الأعضاء'!M6:M505,"Active",'MEMBER REGISTRY | سجل الأعضاء'!H6:H505,"Monthly Unlimited")
B9: Dedicated Desk (active) | مكتب مخصص | C9: =COUNTIFS('MEMBER REGISTRY | سجل الأعضاء'!M6:M505,"Active",'MEMBER REGISTRY | سجل الأعضاء'!H6:H505,"Dedicated Desk")
B10: Expired / Churned | منتهي / مغادر | C10: =COUNTIF('MEMBER REGISTRY | سجل الأعضاء'!M6:M505,"Expired")
B11: Suspended | معلّق | C11: =COUNTIF('MEMBER REGISTRY | سجل الأعضاء'!M6:M505,"Suspended")
B12: Total Registered (all time) | إجمالي المسجلين | C12: =COUNTA('MEMBER REGISTRY | سجل الأعضاء'!A6:A505)
B14: MONTHLY RECURRING REVENUE (MRR) | الإيراد الشهري المتكرر
B15: Flex × $30 | مرن × ٣٠ دولار | C15: =COUNTIFS('MEMBER REGISTRY | سجل الأعضاء'!M6:M505,"Active",'MEMBER REGISTRY | سجل الأعضاء'!H6:H505,"Monthly Flex (8 days)")*30
B16: Unlimited × $60 | غير محدود × ٦٠ دولار | C16: =COUNTIFS('MEMBER REGISTRY | سجل الأعضاء'!M6:M505,"Active",'MEMBER REGISTRY | سجل الأعضاء'!H6:H505,"Monthly Unlimited")*60
B17: Dedicated × $90 | مخصص × ٩٠ دولار | C17: =COUNTIFS('MEMBER REGISTRY | سجل الأعضاء'!M6:M505,"Active",'MEMBER REGISTRY | سجل الأعضاء'!H6:H505,"Dedicated Desk")*90
B18: TOTAL MRR (USD) | إجمالي الإيراد الشهري | C18: =SUM(C15:C17)
B19: TOTAL MRR (YER) | ريال يمني | C19: =C18*1700
B21: CONVERSION & UTILIZATION | التحويل والاستخدام
B22: Total Day Passes Sold (all time) | إجمالي التصاريح المباعة | C22: =COUNTA('DAY PASS LOG | سجل التصاريح'!C5:C1004)
B23: Day Passes Converted to Member | تصاريح تحولت لعضوية | C23: =COUNTIF('CONVERSION FUNNEL | قمع التحويل'!M5:M504,"Yes")
B24: Conversion Rate % | نسبة التحويل | C24: =IF(C22=0,0,C23/C22)
B25: Renewals Due in 7 Days | تجديدات مستحقة خلال ٧ أيام | C25: =COUNTIFS('RENEWAL TRACKER | متتبع التجديد'!E5:E504,">0",'RENEWAL TRACKER | متتبع التجديد'!E5:E504,"<=7")
B26: Overdue Renewals | تجديدات متأخرة | C26: =COUNTIF('RENEWAL TRACKER | متتبع التجديد'!F5:F504,"OVERDUE")
B27: Workspace Capacity (seats) | السعة (مقاعد) | C27: 14
B28: Target Occupancy M6 | هدف الإشغال شهر ٦ | C28: 60%
B30: ACQUISITION SOURCE | مصدر الاكتساب
B31: Walk-in | C31: =COUNTIF('MEMBER REGISTRY | سجل الأعضاء'!Y6:Y505,"Walk-in")
B32: Referral | C32: =COUNTIF('MEMBER REGISTRY | سجل الأعضاء'!Y6:Y505,"Referral")
B33: Social Media | C33: =COUNTIF('MEMBER REGISTRY | سجل الأعضاء'!Y6:Y505,"Social Media")
B34: Open Doors Day | C34: =COUNTIF('MEMBER REGISTRY | سجل الأعضاء'!Y6:Y505,"Open Doors Day")
B35: Event | C35: =COUNTIF('MEMBER REGISTRY | سجل الأعضاء'!Y6:Y505,"Event")
B36: WhatsApp | C36: =COUNTIF('MEMBER REGISTRY | سجل الأعضاء'!Y6:Y505,"WhatsApp")
B37: Website | C37: =COUNTIF('MEMBER REGISTRY | سجل الأعضاء'!Y6:Y505,"Website")
B38: University | C38: =COUNTIF('MEMBER REGISTRY | سجل الأعضاء'!Y6:Y505,"University")
B39: INGO | C39: =COUNTIF('MEMBER REGISTRY | سجل الأعضاء'!Y6:Y505,"INGO")
B40: Partner | C40: =COUNTIF('MEMBER REGISTRY | سجل الأعضاء'!Y6:Y505,"Partner")

Sheet PRICING | مرجع الأسعار
B1: KAYAN HUB PRICING CARD | بطاقة أسعار كيان هب | Effective 1 May 2026
B2: Source: KAY-LEG-WMA-001 Article 1 | Exchange Rate: dated Aden market rate (LOCKED) | DO NOT MODIFY without CEO written approval
B4: Plan | الخطة | C4: Price USD السعر دولار | D4: Price YER السعر ريال | E4: Includes | يشمل | F4: Discount Authority صلاحية الخصم
B5: Day Pass | تصريح يومي | C5: 5 | D5: 8500 | E5: Desk + Wi-Fi + basic café discount. Valid same day only. | F5: No discount. Fixed price.
B6: Half-Day / Evening | نصف يوم / مسائي | C6: 3 | D6: 5100 | E6: 4-hour access, off-peak hours only. | F6: No discount. Fixed price.
B7: Monthly Flex (8 days) | شهري مرن (٨ أيام) | C7: 30 | D7: 51000 | E7: Prepaid 8-day access per month. Non-transferable. Fair-use Wi-Fi. | F7: CEO only: max 10% for 3+ month prepay
B8: Monthly Unlimited | شهري غير محدود | C8: 60 | D8: 102000 | E8: Full daily access Sat-Thu 8AM-8PM. Fair-use Wi-Fi. Café member pricing. | F8: CEO only: max 15% for 6+ month prepay
B9: Dedicated Desk | مكتب مخصص | C9: 90 | D9: 153000 | E9: Reserved desk + locker + after-hours key access + priority booking. | F9: CEO only: max 10% for 6+ month prepay
B10: Meeting Room | غرفة اجتماعات | C10: 10 | D10: 17000 | E10: Per hour. 8 persons max. Projector + whiteboard included. | F10: Workspace Lead: 1 free hour for Unlimited/Dedicated members per month
B11: Training Hall — Half Day | قاعة تدريب — نصف يوم | C11: 40 | D11: 68000 | E11: 4 hours. 20 persons max. All equipment. | F11: CEO + Tariq: INGO/donor rate negotiable
B12: Training Hall — Full Day | قاعة تدريب — يوم كامل | C12: 70 | D12: 119000 | E12: 8 hours. 20 persons max. All equipment. | F12: CEO + Tariq: INGO/donor rate negotiable
B15: ⚠ HARD RULE: No free memberships without CEO + Tariq written approval. No discount above DOA thresholds. Every exception documented.

Sheet RISK & ACCOUNTABILITY | المخاطر
B1: RISK & ACCOUNTABILITY REGISTER | سجل المخاطر والمساءلة | KAY-OPS-MMS-001 Tab 9
B2: ⚖ Items marked require counsel validation per KAY-LEG-011 Phase 2. Cross-ref: KAY-DAT-001, KAY-COM-PDP-001, KAY-SAF-001
B4: ID | C4: Risk | المخاطر | D4: Likelihood الاحتمال | E4: Impact الأثر | F4: Mitigation & Controls | التخفيف والضوابط | G4: Accountable المسؤول | H4: Counsel Ref. مرجع المحامي
B5: MR-01 | C5: ⚖ Member personal data breach اختراق بيانات الأعضاء الشخصية | D5: Medium | E5: High | F5: File password-protected. Google Drive encrypted. No screenshots. Staff trained on KAY-DAT-001. Access restricted to Workspace Lead + CEO. Daily backup. | G5: Workspace Lead | H5: Phase 2(f)
B6: MR-02 | C6: ⚖ Incomplete member consent forms نماذج موافقة غير مكتملة | D6: Medium | E6: High | F6: Check-in refuses entry without signed Handbook + Agreement (columns V, W in Registry). CCTV consent collected at registration. Photo opt-out tracked. | G6: Reception Staff | H6: Phase 2(f)(k)
B7: MR-03 | C7: Revenue leakage — unlogged day passes تسرب الإيرادات — تصاريح غير مسجلة | D7: Medium | E7: High | F7: Day Pass Log reconciles daily with cash form KAY-OPS-CHK-001. Receipt # mandatory. Any mismatch = incident report. CCTV covers reception. | G7: Workspace Lead | H7: —
B8: MR-04 | C8: Unauthorized persons in workspace أشخاص غير مرخصين في المساحة | D8: Medium | E8: Medium | F8: Every entry logged. Guest policy max 2 per member. Valid ID required. Security walk 3x daily. CCTV at entrance. | G8: Reception Staff | H8: —
B9: MR-05 | C9: ⚖ Member liability dispute (lost items) نزاع مسؤولية عضو (أغراض مفقودة) | D9: Medium | E9: Medium | F9: Liability waiver in KAY-CON-012 Art.3.3 & KAY-OPS-HBK-001 §2.7. Lockers for Dedicated Desk. CCTV evidence. | G9: Workspace Lead | H9: Phase 2(f)
B10: MR-06 | C10: Renewal tracking failure — silent churn فشل تتبع التجديد — مغادرة صامتة | D10: High | E10: High | F10: Renewal Tracker tab with auto-calculated expiry alerts. 7-day advance contact. CEO reviews weekly. Churn reason logged for improvement. | G10: Workspace Lead | H10: —
B11: MR-07 | C11: ⚖ Member ID data misuse or theft إساءة استخدام أو سرقة بيانات الهوية | D11: Low | E11: Critical | F11: National ID stored as last 3 digits only (***789). Full ID verified at registration but NOT stored digitally. Physical forms in locked cabinet. | G11: CEO | H11: Phase 2(f)
B12: MR-08 | C12: Conversion funnel not tracked — revenue stagnation عدم تتبع قمع التحويل — ركود الإيرادات | D12: High | E12: High | F12: Conversion Funnel tab mandatory for every day pass buyer. CEO reviews conversion rate weekly. Target: 15% by M6. Below 10% = strategy review. | G12: CEO | H12: —
B13: MR-09 | C13: ⚖ Emergency contact data handling التعامل مع بيانات جهة اتصال الطوارئ | D13: Low | E13: Medium | F13: Emergency contact used ONLY for medical/safety emergencies. Not for marketing. Not shared. Consent collected on membership form. | G13: Workspace Lead | H13: Phase 2(f)
B14: MR-10 | C14: System failure — file corruption or loss فشل النظام — تلف أو فقدان الملف | D14: Medium | E14: Critical | F14: Daily Google Drive auto-sync. Weekly manual backup to USB. Monthly backup to separate cloud. Version history enabled. | G14: Workspace Lead | H14: —
