Workbook
Name AgeBands: '01_CONFIG'!$D$43:$D$48
Name Availability: '01_CONFIG'!$E$43:$E$47
Name BudgetBands: '01_CONFIG'!$B$57:$B$62
Name Channels: '01_CONFIG'!$D$18:$D$27
Name Countries: '01_CONFIG'!$B$18:$B$38
Name Currencies: '01_CONFIG'!$C$18:$C$25
Name Domains: '01_CONFIG'!$G$18:$G$25
Name EOIStatus: '01_CONFIG'!$E$18:$E$26
Name Genders: '01_CONFIG'!$C$43:$C$45
Name Industries: '01_CONFIG'!$C$57:$C$68
Name Languages: '01_CONFIG'!$E$57:$E$61
Name OrgSizes: '01_CONFIG'!$D$57:$D$61
Name Tiers: '01_CONFIG'!$F$18:$F$22
Name YesNo: '01_CONFIG'!$B$43:$B$44

Sheet 00_INDEX
A1: KAYAN · PRE-LAUNCH FORMS PACK حزمة نماذج التسجيل قبل الإطلاق
A3: Doc ID: KAY-TECH-FORMS-001 · Version: v1.0 FINAL · Date: 19 Apr 2026 · Owner: CEO — Maher · Status: APPROVED FOR CAPTURE
A5: WORKBOOK NAVIGATION / دليل الملف
A6: # | B6: Tab | C6: Purpose (EN) | D6: Arabic / العربية | E6: Audience | F6: Channel
A7: 01 | B7: 01_CONFIG | C7: Master config: FX, codes, dropdowns, schema registry | D7: الإعدادات الرئيسية | E7: Internal / Tech | F7: All
A8: 02 | B8: 02_EOI_CLIENT | C8: Business / client Expression of Interest — 15 fields | D8: نموذج اهتمام العميل | E8: External | F8: Web + WA
A9: 03 | B9: 03_EOI_FREELANCER | C9: Talent EOI — skills tier, micro-spec, availability | D9: نموذج اهتمام المستقل | E9: External | F9: Web + WA
A10: 04 | B10: 04_EOI_BUSINESS | C10: SME / partner business EOI — hiring + space + academy | D10: نموذج الشركة الشريكة | E10: External | F10: Web
A11: 05 | B11: 05_EOI_VOLUNTEER | C11: FAEAN volunteer EOI — cause, availability, skills | D11: نموذج المتطوع فعان | E11: External | F11: Web + WA
A12: 06 | B12: 06_EOI_ACADEMY | C12: Academy learner EOI — track, level, availability | D12: نموذج متعلم الأكاديمية | E12: External | F12: Web + WA
A13: 07 | B13: 07_EOI_HUB | C13: Hub space enquiry — desk, room, event, membership | D13: نموذج الاستفسار عن المساحة | E13: External | F13: Web + WA
A14: 08 | B14: 08_REG_CLIENT_FULL | C14: Full client registration (activated 01 Jun) — KYC | D14: تسجيل كامل للعميل | E14: External | F14: Platform
A15: 09 | B15: 09_REG_TALENT_FULL | C15: Full talent registration — KYC + portfolio + score | D15: تسجيل كامل للمستقل | E15: External | F15: Platform
A16: 10 | B16: 10_REG_VOLUNTEER_FULL | C16: Full volunteer registration — background + consent | D16: تسجيل كامل للمتطوع | E16: External | F16: Platform
A17: 11 | B17: 11_HUB_BOOKING | C17: Space booking form — date, time, seat, invoice | D17: نموذج حجز المساحة | E17: External | F17: Web + WA
... A23: 17 | B23: 17_KPI_DASH | C23: Pre-launch KPI dashboard — targets vs actuals | D23: لوحة مؤشرات الأداء | E23: CEO + Ops | F23: Internal
A26: LEGEND / دليل الألوان
A27: Blue text | B27: Hardcoded inputs — the capture fields users fill in
A28: Black italic | B28: Formulas and calculations
A29: Green text | B29: Cross-sheet references (e.g., CONFIG lookups)
A30: Yellow fill | B30: Key attention cells — assumptions, targets, limits
A31: Red asterisk (comment) | B31: Required field — form cannot submit without it
A34: COMMISSIONING & SIGN-OFF / اعتماد الوثيقة
A35: Commissioned by: | B35: Maher — CEO, Kayan Innovation LLC
A36: Prepared by: | B36: Kayan Tech OS Authoring — in line with KAY-TECH-OS-008 v8.0
A37: Effective from: | B37: 19 Apr 2026 — EOI capture opens 25 Apr 2026

Sheet 01_CONFIG
A1: MASTER CONFIGURATION / الإعدادات الرئيسية
A3: Single source of truth. Do not hardcode dropdowns anywhere else — always point to the named ranges in this sheet.
A5: A. CONSTITUTIONAL ANCHORS — HARDCODED
A6: # | B6: Key | C6: Value | D6: Purpose / ملاحظة
A7: 1 | B7: FX_RATE_USD_YER | D7: YER per 1 USD — locked per SHA, non-negotiable
A8: 2 | B8: OPEX_CEILING_USD_MO | D8: Total monthly OPEX ceiling
A9: 3 | B9: TECH_SUBCEILING_USD_MO | D9: Tech sub-ceiling within OPEX
A10: 4 | B10: ESCROW_LIABILITY_PCT | D10: 2170 rule — liability reserve
A11: 5 | B11: ESCROW_SETTLE_PCT | D11: 2170 rule — contractor/pod settlement
A12: 6 | B12: ESCROW_FEE_PCT | D12: 2170 rule — Kayan platform fee
A13: 7 | B13: VAT_PCT | D13: Yemen VAT (n/a currently; kept for future)
A14: 8 | B14: WHT_PCT | D14: Withholding tax — currently accrued, remit at Tadamon opening
A16: B. CODE REGISTRIES — used across all tabs (named ranges)
B17: Countries | C17: Currencies | D17: Intake Channels | E17: EOI Status | F17: Verification Tiers | G17: Domains
B18: Yemen / اليمن | C18: USD | D18: Web form | E18: Received | F18: T0 — Unverified | G18: 1 · Technology
B19: Egypt / مصر | C19: YER | D19: WhatsApp | E19: Contacted | F19: T1 — ID verified | G19: 2 · Creative & Media
B20: Saudi Arabia / السعودية | C20: SAR | D20: In-person (Hub) | E20: Qualified | F20: T2 — Skill verified | G20: 3 · Business & Finance
B21: UAE / الإمارات | C21: AED | D21: Referral | E21: Scheduled | F21: T3 — Project-proven | G21: 4 · Training & Education
B22: Jordan / الأردن | C22: EGP | D22: Social (IG/FB/X/LI) | E22: Converted | F22: T4 — Elite (Kayan Select) | G22: 5 · Research & Analysis
B23: Oman / عُمان | C23: EUR | D23: Academy | E23: Declined | G23: 6 · Consulting & Advisory
B24: Kuwait / الكويت | C24: GBP | D24: Event / Workshop | E24: On hold | G24: 7 · Physical & Field
B25: Bahrain / البحرين | C25: Other | D25: Email | E25: Duplicate | G25: 8 · Specialist
B26: Qatar / قطر | D26: Phone | E26: Spam
B27: Lebanon / لبنان | D27: Partner org
B28: Iraq / العراق
B29: Sudan / السودان
B30: Morocco / المغرب
B31: Tunisia / تونس
B32: Algeria / الجزائر
B33: Palestine / فلسطين
B34: Turkey / تركيا
B35: UK / المملكة المتحدة
B36: USA / الولايات المتحدة
B37: Germany / ألمانيا
B38: Other / أخرى
A41: C. ADDITIONAL LOOKUPS
B42: YesNo | C42: Genders | D42: AgeBands | E42: Availability
B43: Yes / نعم | C43: Female / أنثى | D43: Under 18 | E43: Full-time (40 hrs/wk)
B44: No / لا | C44: Male / ذكر | D44: 18-24 | E44: Part-time (20 hrs/wk)
C45: Prefer not to say / أفضل عدم القول | D45: 25-34 | E45: Evenings / weekends
...

Sheet 02_EOI_CLIENT
A1: CLIENT — EXPRESSION OF INTEREST نموذج اهتمام العميل التجاري
A3: Sheet code: CL · Version: v1.0 · Bilingual AR/EN · Mobile + WhatsApp compatible · Constitutional FX: 1 USD = 1,700 YER
A4: Thank you for considering Kayan. This short form starts the conversation. No commitment yet — we simply want to understand what you need so we can route you to the right pod and schedule a scoping call within 48 hours. شكراً لاهتمامك بكيان. هذا نموذج مختصر لبدء الحوار — لا يُلزمك بشيء. نود فقط أن نفهم ما تحتاج إليه لنوجهك إلى الفريق المناسب وننظم لقاء توضيحي خلال 48 ساعة.
A7: A. Contact / بيانات التواصل
A8: 1 | B8: Full name الاسم الكامل | E8: Required
A9: 2 | B9: Role / position المنصب | E9: Required
A10: 3 | B10: Company name اسم الشركة | E10: Required
A11: 4 | B11: Work email البريد الإلكتروني | E11: Required
A12: 5 | B12: Mobile / WhatsApp الجوال / واتساب | E12: Required
A13: 6 | B13: Country الدولة | E13: Required
A14: 7 | B14: City المدينة | E14: Required
A15: 8 | B15: Preferred language اللغة المفضلة | E15: Required
A16: 9 | B16: Preferred contact channel القناة المفضلة للتواصل | E16: Required
A17: B. Company / عن الشركة
A18: 10 | B18: Industry القطاع | E18: Required
A19: 11 | B19: Company size حجم الشركة | E19: Required
A20: 12 | B20: Website (if any) الموقع الإلكتروني (إن وجد) | E20: Optional
A21: 13 | B21: Is your company registered? هل شركتك مسجلة رسمياً؟ | E21: Required
A22: C. Project & need / المشروع والحاجة
A23: 14 | B23: Headline: what do you want to get done? عنوان مختصر: ما الذي تريد إنجازه؟ | E23: Required
A24: 15 | B24: Describe the project / problem وصف المشروع / المشكلة | E24: Required
A25: 16 | B25: Core specialization needed التخصص الأساسي المطلوب | E25: Required
A26: 17 | B26: Budget band شريحة الميزانية | E26: Required
A27: 18 | B27: Preferred currency العملة المفضلة | E27: Required
A28: 19 | B28: Desired start date تاريخ البدء المطلوب | E28: Optional
A29: 20 | B29: Desired finish date تاريخ الإنجاز المطلوب | E29: Optional
A30: 21 | B30: Must have escrow protection (2170)? هل تحتاج حماية الضمان (قاعدة 2170)؟ | E30: Required
A31: D. How did you hear about us? / كيف سمعت عنا؟
A32: 22 | B32: Channel القناة | E32: Required
A33: 23 | B33: Referred by (name, if any) اسم من أوصى بنا (إن وُجد) | E33: Optional
A35: CONSENT & SUBMISSION META / الموافقة وبيانات الإرسال
A36: ☐ | B36: I consent to Kayan storing my data for EOI processing. أوافق على احتفاظ كيان ببياناتي لمعالجة اهتمامي. | E36: Required
A37: ☐ | B37: I agree to be contacted by Kayan through the channel I specified. أوافق على أن تتواصل كيان معي عبر القناة التي اخترتها. | E37: Required
A38: ☐ | B38: I confirm that all information provided is accurate to the best of my knowledge. أؤكد أن جميع المعلومات دقيقة حسب معرفتي. | E38: Required
A39: ☐ | B39: I am happy to receive updates (newsletter, events, opportunities). أرغب في تلقي التحديثات (النشرة والأحداث والفرص). | E39: Optional
A41: INTERNAL USE ONLY / لاستعمال الفريق فقط
B42: Submission ID (auto) معرّف الطلب | D42: ="KYN-CL-"&TEXT(TODAY(),"YYYYMMDD")&"-"&TEXT(RANDBETWEEN(1000,9999),"0000") -> KYN-CL-20260609-5372 | E42: Internal
B43: Received timestamp تاريخ الاستلام | D43: =NOW() -> 46182.775 | E43: Internal
B44: Intake channel قناة الاستلام | E44: Internal
B45: Assigned handler الموظف المسؤول | E45: Internal
...

Sheet 03_EOI_FREELANCER
A1: FREELANCER / TALENT — EXPRESSION OF INTEREST نموذج اهتمام المستقل / الموهبة
A3: Sheet code: TL · Version: v1.0 · Bilingual AR/EN · Mobile + WhatsApp compatible · Constitutional FX: 1 USD = 1,700 YER
A4: Kayan is building a verified, escrow-protected talent network. This EOI is the doorway. We do not hide behind forms — once you submit, a human handler will reach you within 48 hours to walk you through verification and, if you are a fit, issue your Kayan Card (T2). كيان تبني شبكة موثوقة من المستقلين بحماية ضمان. هذا النموذج هو البداية. بمجرد إرسال اهتمامك سيتواصل معك أحد أعضاء الفريق خلال 48 ساعة لشرح خطوات التحقق، وإن كنتَ مناسباً نُصدر لك بطاقة كيان (المستوى T2).
A7: A. Personal / بياناتك
A8: 1 | B8: Full name الاسم الكامل | E8: Required
A9: 2 | B9: Gender الجنس | E9: Optional
A10: 3 | B10: Age band الفئة العمرية | E10: Required
A11: 4 | B11: Email البريد الإلكتروني | E11: Required
A12: 5 | B12: Mobile / WhatsApp الجوال / واتساب | E12: Required
A13: 6 | B13: Country of residence بلد الإقامة | E13: Required
A14: 7 | B14: City المدينة | E14: Required
A15: 8 | B15: Working languages لغات العمل | E15: Required
A16: B. Skill & specialization / المهارة والتخصص
A17: 9 | B17: Primary domain القطاع الأساسي | E17: Required
A18: 10 | B18: Top 3 micro-specializations (codes) أبرز 3 تخصصات دقيقة (الرموز) | E18: Required
A19: 11 | B19: Years of professional experience سنوات الخبرة المهنية | E19: Required
A20: 12 | B20: Current title / role المسمى الوظيفي الحالي | E20: Required
A21: 13 | B21: Portfolio / GitHub / Behance URL رابط أعمالك | E21: Optional
A22: 14 | B22: LinkedIn URL رابط لينكدإن | E22: Optional
A23: 15 | B23: Short bio (3-5 sentences) نبذة تعريفية (3-5 جُمل) | E23: Required
A24: C. Availability & rate / التوفر والأجر
A25: 16 | B25: Availability التوفر | E25: Required
A26: 17 | B26: Hours per week you can commit عدد الساعات أسبوعياً | E26: Required
A27: 18 | B27: Preferred currency العملة المفضلة | E27: Required
A28: 19 | B28: Hourly rate (in preferred currency) السعر بالساعة | E28: Required
A29: 20 | B29: Open to pod / team collaboration? هل ترغب بالعمل ضمن فريق؟ | E29: Required
A30: 21 | B30: Ready to accept escrow terms (2170)? هل تقبل شروط الضمان (2170)؟ | E30: Required
A31: D. Verification prep / تمهيد التحقق
A32: 22 | B32: Government-issued ID available? هل لديك هوية رسمية؟ | E32: Required
A33: 23 | B33: Willing to complete a short skill test? هل توافق على اختبار مهاري قصير؟ | E33: Required
A34: 24 | B34: References available on request? هل بالإمكان تقديم مراجع؟ | E34: Optional
A35: E. Discovery / كيف عرفت كيان
A36: 25 | B36: Channel القناة | E36: Required
A37: 26 | B37: Referred by بواسطة | E37: Optional
A39: CONSENT & SUBMISSION META / الموافقة وبيانات الإرسال
A40: ☐ | B40: I consent to Kayan storing my data for EOI processing. أوافق على احتفاظ كيان ببياناتي لمعالجة اهتمامي. | E40: Required
A41: ☐ | B41: I agree to be contacted by Kayan through the channel I specified. أوافق على أن تتواصل كيان معي عبر القناة التي اخترتها. | E41: Required
A42: ☐ | B42: I confirm that all information provided is accurate to the best of my knowledge. أؤكد أن جميع المعلومات دقيقة حسب معرفتي. | E42: Required
A43: ☐ | B43: I am happy to receive updates (newsletter, events, opportunities). أرغب في تلقي التحديثات (النشرة والأحداث والفرص). | E43: Optional
A45: INTERNAL USE ONLY / لاستعمال الفريق فقط
...

Sheet 04_EOI_BUSINESS
A1: BUSINESS / PARTNER — EXPRESSION OF INTEREST نموذج اهتمام الشركات والشركاء
A3: Sheet code: BZ · Version: v1.0 · Bilingual AR/EN · Mobile + WhatsApp compatible · Constitutional FX: 1 USD = 1,700 YER
A4: Kayan is a complete business system — managed delivery, verified talent pods, co-working hub, and academy. This form helps us see which of these matters most to your company so we can send the most relevant package, not a generic pitch. كيان نظام أعمال متكامل: تنفيذ مُدار، فرق موهبة موثّقة، مساحة عمل، أكاديمية تدريب. هذا النموذج يساعدنا على إرسال الحزمة الأنسب لشركتك فعلاً — لا عرضاً عاماً.
A7: A. Contact / جهة التواصل
A8: 1 | B8: Decision-maker full name الاسم الكامل لصاحب القرار | E8: Required
A9: 2 | B9: Role المنصب | E9: Required
A10: 3 | B10: Company name اسم الشركة | E10: Required
A11: 4 | B11: Work email البريد الإلكتروني | E11: Required
A12: 5 | B12: Mobile / WhatsApp الجوال / واتساب | E12: Required
A13: 6 | B13: Country الدولة | E13: Required
A14: 7 | B14: City المدينة | E14: Required
A15: B. Company profile / ملف الشركة
A16: 8 | B16: Industry القطاع | E16: Required
A17: 9 | B17: Company size حجم الشركة | E17: Required
A18: 10 | B18: Year founded سنة التأسيس | E18: Required
A19: 11 | B19: Website الموقع الإلكتروني | E19: Optional
A20: 12 | B20: One-line business description وصف الشركة في سطر | E20: Required
A21: C. Interest in Kayan / الاهتمام بكيان
A22: 13 | B22: Interested in managed delivery (projects)? مهتم بخدمة التنفيذ المُدار؟ | E22: Required
A23: 14 | B23: Interested in hiring talent pods? مهتم بتوظيف فرق عمل (Pods)؟ | E23: Required
A24: 15 | B24: Interested in hub / co-working space? مهتم بمساحة العمل المشتركة؟ | E24: Required
A25: 16 | B25: Interested in Academy training for your team? مهتم بتدريب الفريق عبر الأكاديمية؟ | E25: Required
A26: 17 | B26: Interested in Kayan as a supplier / vendor? مهتم بكيان كمورّد / متعاقد؟ | E26: Required
A27: 18 | B27: Interested in co-marketing / partnership? مهتم بالشراكة التسويقية؟ | E27: Required
A28: 19 | B28: Annual spend estimate for managed services (USD) الإنفاق السنوي التقديري على الخدمات ($) | E28: Optional
A29: D. Need detail / تفاصيل الحاجة
A30: 20 | B30: What are your top 3 priorities in the next 6 months? ما أبرز ثلاث أولويات خلال 6 أشهر؟ | E30: Required
A31: 21 | B31: Are there active projects we can quote on now? هل هناك مشاريع نشطة يمكننا تسعيرها الآن؟ | E31: Optional
A32: E. Discovery / كيف عرفت كيان
A33: 22 | B33: Channel القناة | E33: Required
A34: 23 | B34: Referred by بواسطة | E34: Optional
A36: CONSENT & SUBMISSION META / الموافقة وبيانات الإرسال
A37: ☐ | B37: I consent to Kayan storing my data for EOI processing. أوافق على احتفاظ كيان ببياناتي لمعالجة اهتمامي. | E37: Required
A38: ☐ | B38: I agree to be contacted by Kayan through the channel I specified. أوافق على أن تتواصل كيان معي عبر القناة التي اخترتها. | E38: Required
A39: ☐ | B39: I confirm that all information provided is accurate to the best of my knowledge. أؤكد أن جميع المعلومات دقيقة حسب معرفتي. | E39: Required
A40: ☐ | B40: I am happy to receive updates (newsletter, events, opportunities). أرغب في تلقي التحديثات (النشرة والأحداث والفرص). | E40: Optional
A42: INTERNAL USE ONLY / لاستعمال الفريق فقط
B43: Submission ID (auto) معرّف الطلب | D43: ="KYN-BZ-"&TEXT(TODAY(),"YYYYMMDD")&"-"&TEXT(RANDBETWEEN(1000,9999),"0000") -> KYN-BZ-20260609-7929 | E43: Internal
B44: Received timestamp تاريخ الاستلام | D44: =NOW() -> 46182.775 | E44: Internal
B45: Intake channel قناة الاستلام | E45: Internal
...

Sheet 05_EOI_VOLUNTEER
A1: FAEAN VOLUNTEER — EXPRESSION OF INTEREST نموذج اهتمام متطوع فعّان
A3: Sheet code: VL · Version: v1.0 · Bilingual AR/EN · Mobile + WhatsApp compatible · Constitutional FX: 1 USD = 1,700 YER
A4: FAEAN is Kayan's community-impact arm — volunteers who turn goodwill into measurable action. Tell us which causes move you, what you can offer, and how much time you can give. Every volunteer is matched to a mission where their specific skills land. فعّان هو الذراع المجتمعية لكيان — متطوعون يحوّلون النية الطيبة إلى أثر قابل للقياس. أخبرنا بالقضايا التي تهمك، وماذا يمكنك تقديمه، وكم من الوقت لديك. كل متطوع يُطابق مع مهمة تتناسب مع مهاراته.
A7: A. Personal / بياناتك
A8: 1 | B8: Full name الاسم الكامل | E8: Required
A9: 2 | B9: Gender الجنس | E9: Optional
A10: 3 | B10: Age band الفئة العمرية | E10: Required
A11: 4 | B11: Email البريد الإلكتروني | E11: Required
A12: 5 | B12: Mobile / WhatsApp الجوال / واتساب | E12: Required
A13: 6 | B13: Country الدولة | E13: Required
A14: 7 | B14: City / district المدينة / الحي | E14: Required
A15: B. Causes you care about / القضايا التي تهمك
A16: 8 | B16: Education & literacy التعليم ومحو الأمية | E16: Optional
A17: 9 | B17: Youth employment توظيف الشباب | E17: Optional
A18: 10 | B18: Women's economic empowerment تمكين المرأة اقتصادياً | E18: Optional
A19: 11 | B19: Health & wellbeing الصحة والعافية | E19: Optional
A20: 12 | B20: Environment / sustainability البيئة والاستدامة | E20: Optional
A21: 13 | B21: Community building & events بناء المجتمع والفعاليات | E21: Optional
A22: 14 | B22: Emergency / humanitarian response الاستجابة الإنسانية والطوارئ | E22: Optional
A23: C. Skills you can offer / المهارات التي يمكنك تقديمها
A24: 15 | B24: Primary skill domain مجال المهارة الأساسي | E24: Required
A25: 16 | B25: Specific skills (brief list) المهارات المحددة (قائمة مختصرة) | E25: Required
A26: 17 | B26: Languages اللغات | E26: Required
A27: D. Availability / التوفر
A28: 18 | B28: Hours per month you can commit عدد الساعات شهرياً | E28: Required
A29: 19 | B29: Availability pattern نمط التوفر | E29: Required
A30: 20 | B30: Open to remote, in-person, or both? عن بعد، حضوري، أم كلاهما؟ | E30: Required
A31: 21 | B31: When can you start? متى يمكنك البدء؟ | E31: Required
A32: E. Commitment & consent / الالتزام والموافقة
A33: 22 | B33: Why do you want to volunteer with FAEAN? لماذا ترغب بالتطوع مع فعّان؟ | E33: Required
A34: 23 | B34: Consent to background check (for youth-facing roles)? موافقة على التحقق (للأدوار المتعلقة بالشباب) | E34: Required
A35: 24 | B35: Emergency contact name اسم جهة الاتصال في الطوارئ | E35: Optional
A36: 25 | B36: Emergency contact phone هاتف جهة الاتصال في الطوارئ | E36: Optional
A37: F. Discovery / كيف عرفت فعان
A38: 26 | B38: Channel القناة | E38: Required
A39: 27 | B39: Referred by بواسطة | E39: Optional
A41: CONSENT & SUBMISSION META / الموافقة وبيانات الإرسال
A42: ☐ | B42: I consent to Kayan storing my data for EOI processing. أوافق على احتفاظ كيان ببياناتي لمعالجة اهتمامي. | E42: Required
A43: ☐ | B43: I agree to be contacted by Kayan through the channel I specified. أوافق على أن تتواصل كيان معي عبر القناة التي اخترتها. | E43: Required
A44: ☐ | B44: I confirm that all information provided is accurate to the best of my knowledge. أؤكد أن جميع المعلومات دقيقة حسب معرفتي. | E44: Required
...

Sheet 06_EOI_ACADEMY
A1: ACADEMY LEARNER — EXPRESSION OF INTEREST نموذج اهتمام متعلم الأكاديمية
A3: Sheet code: AC · Version: v1.0 · Bilingual AR/EN · Mobile + WhatsApp compatible · Constitutional FX: 1 USD = 1,700 YER
A4: Kayan Academy is practice-first: every track ends with a real-world project that pays, not a slide deck. Tell us where you are and where you want to go — we will match you to a cohort or a self-paced path. أكاديمية كيان تركز على التطبيق: كل مسار ينتهي بمشروع عملي مُدفَّع الأجر — لا بشرائح فقط. أخبرنا بمكانك الحالي ووجهتك، وسنرشدك إلى الدفعة أو المسار المناسب.
A7: A. Personal / بياناتك
A8: 1 | B8: Full name الاسم الكامل | E8: Required
A9: 2 | B9: Gender الجنس | E9: Optional
A10: 3 | B10: Age band الفئة العمرية | E10: Required
A11: 4 | B11: Email البريد الإلكتروني | E11: Required
A12: 5 | B12: Mobile / WhatsApp الجوال / واتساب | E12: Required
A13: 6 | B13: Country الدولة | E13: Required
A14: 7 | B14: City المدينة | E14: Required
A15: B. Background / الخلفية
A16: 8 | B16: Current status (student / employed / job-seeking / other) الوضع الحالي | E16: Required
A17: 9 | B17: Education level المستوى التعليمي | E17: Required
A18: 10 | B18: Working languages لغات العمل | E18: Required
A19: C. Track of interest / المسار المطلوب
A20: 11 | B20: Primary domain القطاع الأساسي | E20: Required
A21: 12 | B21: Specific track / course interest المسار أو الدورة المحددة | E21: Required
A22: 13 | B22: Current skill level in this area المستوى الحالي | E22: Required
A23: 14 | B23: Goal from the course هدفك من الدورة | E23: Required
A24: D. Logistics / الترتيبات
A25: 15 | B25: Preferred format الصيغة المفضلة | E25: Required
A26: 16 | B26: Hours per week you can dedicate عدد الساعات أسبوعياً | E26: Required
A27: 17 | B27: Preferred schedule الجدول المفضل | E27: Required
A28: 18 | B28: Can you pay for the course? هل يمكنك دفع رسوم الدورة؟ | E28: Required
A29: 19 | B29: Need scholarship / payment plan? تحتاج منحة أو خطة دفع؟ | E29: Required
A30: E. Discovery / كيف عرفت الأكاديمية
A31: 20 | B31: Channel القناة | E31: Required
A32: 21 | B32: Referred by بواسطة | E32: Optional
A34: CONSENT & SUBMISSION META / الموافقة وبيانات الإرسال
A35: ☐ | B35: I consent to Kayan storing my data for EOI processing. أوافق على احتفاظ كيان ببياناتي لمعالجة اهتمامي. | E35: Required
A36: ☐ | B36: I agree to be contacted by Kayan through the channel I specified. أوافق على أن تتواصل كيان معي عبر القناة التي اخترتها. | E36: Required
A37: ☐ | B37: I confirm that all information provided is accurate to the best of my knowledge. أؤكد أن جميع المعلومات دقيقة حسب معرفتي. | E37: Required
A38: ☐ | B38: I am happy to receive updates (newsletter, events, opportunities). أرغب في تلقي التحديثات (النشرة والأحداث والفرص). | E38: Optional
A40: INTERNAL USE ONLY / لاستعمال الفريق فقط
B41: Submission ID (auto) معرّف الطلب | D41: ="KYN-AC-"&TEXT(TODAY(),"YYYYMMDD")&"-"&TEXT(RANDBETWEEN(1000,9999),"0000") -> KYN-AC-20260609-7465 | E41: Internal
B42: Received timestamp تاريخ الاستلام | D42: =NOW() -> 46182.775 | E42: Internal
B43: Intake channel قناة الاستلام | E43: Internal
B44: Assigned handler الموظف المسؤول | E44: Internal
B45: Status الحالة | E45: Internal
...

Sheet 07_EOI_HUB
A1: HUB / CO-WORKING SPACE — EXPRESSION OF INTEREST نموذج الاستفسار عن مساحة كيان
A3: Sheet code: HB · Version: v1.0 · Bilingual AR/EN · Mobile + WhatsApp compatible · Constitutional FX: 1 USD = 1,700 YER
A4: Kayan Hub is more than a desk — it is the quiet, beautiful place where the work actually gets done. Tell us how you want to use it and we will hold your preferred setup for the opening week. مساحة كيان ليست مجرد مكتب — بل هي المكان الهادئ الجميل حيث يُنجَز العمل فعلاً. أخبرنا كيف تريد استخدامها وسنحجز لك الإعداد المفضل خلال أسبوع الافتتاح.
A7: A. Contact / بيانات التواصل
A8: 1 | B8: Full name الاسم الكامل | E8: Required
A9: 2 | B9: Email البريد الإلكتروني | E9: Required
A10: 3 | B10: Mobile / WhatsApp الجوال / واتساب | E10: Required
A11: 4 | B11: Individual or company? فرد أم شركة؟ | E11: Required
A12: 5 | B12: Company / team name (if any) اسم الفريق أو الشركة | E12: Optional
A13: B. Use of the hub / استخدام المساحة
A14: 6 | B14: What are you looking for? ما الذي تبحث عنه؟ | E14: Required
A15: 7 | B15: Hot desk needed? هل تحتاج مكتب مفتوح؟ | E15: Required
A16: 8 | B16: Dedicated desk needed? مكتب مخصص؟ | E16: Required
A17: 9 | B17: Private office needed? مكتب خاص؟ | E17: Required
A18: 10 | B18: Meeting room needed? قاعة اجتماعات؟ | E18: Required
A19: 11 | B19: Event / workshop space needed? مساحة فعالية؟ | E19: Required
A20: 12 | B20: Mailing / registered address service? خدمة عنوان بريدي؟ | E20: Required
A21: 13 | B21: Number of people / seats عدد الأشخاص أو المقاعد | E21: Required
A22: C. Timing & frequency / التوقيت والتكرار
A23: 14 | B23: Preferred start date تاريخ البدء المفضل | E23: Required
A24: 15 | B24: Frequency (days/week) التكرار (أيام/أسبوع) | E24: Required
A25: 16 | B25: Duration (one-off / weekly / monthly / yearly) المدة | E25: Required
A26: 17 | B26: Preferred hours الأوقات المفضلة | E26: Required
A27: D. Budget & extras / الميزانية والإضافات
A28: 18 | B28: Budget band (USD/month) الميزانية ($ شهرياً) | E28: Required
A29: 19 | B29: Need printing/scanning? تحتاج طباعة/مسح ضوئي؟ | E29: Optional
A30: 20 | B30: Need F&B (café package)? تحتاج خدمة المقهى؟ | E30: Optional
A31: 21 | B31: Need after-hours access? وصول خارج ساعات العمل؟ | E31: Optional
A32: E. Discovery / كيف عرفت المساحة
A33: 22 | B33: Channel القناة | E33: Required
A34: 23 | B34: Referred by بواسطة | E34: Optional
A36: CONSENT & SUBMISSION META / الموافقة وبيانات الإرسال
A37: ☐ | B37: I consent to Kayan storing my data for EOI processing. أوافق على احتفاظ كيان ببياناتي لمعالجة اهتمامي. | E37: Required
A38: ☐ | B38: I agree to be contacted by Kayan through the channel I specified. أوافق على أن تتواصل كيان معي عبر القناة التي اخترتها. | E38: Required
A39: ☐ | B39: I confirm that all information provided is accurate to the best of my knowledge. أؤكد أن جميع المعلومات دقيقة حسب معرفتي. | E39: Required
A40: ☐ | B40: I am happy to receive updates (newsletter, events, opportunities). أرغب في تلقي التحديثات (النشرة والأحداث والفرص). | E40: Optional
A42: INTERNAL USE ONLY / لاستعمال الفريق فقط
B43: Submission ID (auto) معرّف الطلب | D43: ="KYN-HB-"&TEXT(TODAY(),"YYYYMMDD")&"-"&TEXT(RANDBETWEEN(1000,9999),"0000") -> KYN-HB-20260609-3345 | E43: Internal
B44: Received timestamp تاريخ الاستلام | D44: =NOW() -> 46182.775 | E44: Internal
B45: Intake channel قناة الاستلام | E45: Internal
...

Sheet 08_REG_CLIENT_FULL
A1: CLIENT — FULL REGISTRATION (Day 1+) التسجيل الكامل للعميل (بعد الإطلاق)
A3: Sheet code: CLF · Version: v1.0 · Bilingual AR/EN · Mobile + WhatsApp compatible · Constitutional FX: 1 USD = 1,700 YER
A4: Activated on platform opening (01 Jun 2026). Completes KYC / UBO / sanctions / MSA / escrow acceptance. A case manager (Kayan handler) reviews and moves the file through Gates G0 → G3 within 5 business days. يُفعَّل مع افتتاح المنصة (1 يونيو 2026). يُكمل إجراءات اعرف عميلك والمستفيد والعقوبات والاتفاقية الإطارية والضمان. يراجع مدير الحالة الملف وينقله عبر البوابات G0 → G3 خلال 5 أيام عمل.
A7: A. Corporate identity / هوية الشركة
A8: 1 | B8: Legal company name الاسم القانوني للشركة | E8: Required
A9: 2 | B9: Trade name (if different) الاسم التجاري (إن اختلف) | E9: Optional
A10: 3 | B10: Commercial registration # رقم السجل التجاري | E10: Required
A11: 4 | B11: Country of registration بلد التسجيل | E11: Required
A12: 5 | B12: Registered address (street, city, country) العنوان المسجل | E12: Required
A13: 6 | B13: Tax ID / VAT (if applicable) الرقم الضريبي | E13: Optional
A14: 7 | B14: Year founded سنة التأسيس | E14: Required
A15: 8 | B15: Industry القطاع | E15: Required
A16: 9 | B16: Company size حجم الشركة | E16: Required
A17: 10 | B17: Website الموقع الإلكتروني | E17: Optional
A18: B. Beneficial owners (UBO) / الملاك المستفيدون
A19: 11 | B19: UBO 1 — full legal name المستفيد 1 — الاسم القانوني | E19: Required
A20: 12 | B20: UBO 1 — nationality المستفيد 1 — الجنسية | E20: Required
A21: 13 | B21: UBO 1 — ownership % المستفيد 1 — نسبة الملكية | E21: Required
A22: 14 | B22: UBO 2 — full legal name (if any) المستفيد 2 — الاسم (إن وجد) | E22: Optional
A23: 15 | B23: UBO 2 — nationality المستفيد 2 — الجنسية | E23: Optional
A24: 16 | B24: UBO 2 — ownership % المستفيد 2 — النسبة | E24: Optional
A25: 17 | B25: Any UBO a Politically Exposed Person (PEP)? هل أحد الملاك شخصية معرّضة سياسياً؟ | E25: Required
A26: C. Primary contact / جهة التواصل الرئيسية
A27: 18 | B27: Full name الاسم الكامل | E27: Required
A28: 19 | B28: Role المنصب | E28: Required
A29: 20 | B29: Work email البريد الإلكتروني | E29: Required
A30: 21 | B30: Mobile / WhatsApp الجوال / واتساب | E30: Required
A31: 22 | B31: Signature authority (can sign SOW)? صلاحية التوقيع | E31: Required
A32: D. Finance / الشؤون المالية
A33: 23 | B33: Finance contact name اسم مسؤول المالية | E33: Required
A34: 24 | B34: Finance email بريد المالية | E34: Required
A35: 25 | B35: Preferred invoice currency عملة الفاتورة المفضلة | E35: Required
A36: 26 | B36: Payment terms needed (Net X) شروط الدفع | E36: Required
A37: 27 | B37: Bank name اسم البنك | E37: Required
A38: 28 | B38: Bank country بلد البنك | E38: Required
A39: E. Compliance / الالتزام
A40: 29 | B40: Confirmed AML / sanctions declaration? إقرار مكافحة غسل الأموال والعقوبات؟ | E40: Required
A41: 30 | B41: Accept Kayan Master Services Agreement? قبول اتفاقية الخدمات الإطارية؟ | E41: Required
A42: 31 | B42: Accept 2170 escrow model? قبول نموذج الضمان 2170؟ | E42: Required
A43: 32 | B43: Data protection consent (GDPR-equivalent) موافقة حماية البيانات | E43: Required
...

Sheet 09_REG_TALENT_FULL
A1: TALENT — FULL REGISTRATION (Day 1+) التسجيل الكامل للمستقل (بعد الإطلاق)
A3: Sheet code: TLF · Version: v1.0 · Bilingual AR/EN · Mobile + WhatsApp compatible · Constitutional FX: 1 USD = 1,700 YER
A4: Moves a T0 EOI submitter to T2 Skill-Verified — the tier that unlocks the Kayan Card, pod assignment, and paid work. Expected to take ~20 minutes of the talent's time plus a short async skill test. ينقل المتقدم من T0 إلى T2 (موثّق المهارة) — المستوى الذي يفتح بطاقة كيان والتعيين في الفرق والعمل المدفوع. يستغرق نحو 20 دقيقة بالإضافة إلى اختبار مهاري قصير.
A7: A. Identity / الهوية
A8: 1 | B8: Full legal name الاسم القانوني الكامل | E8: Required
A9: 2 | B9: Date of birth تاريخ الميلاد | E9: Required
A10: 3 | B10: Nationality الجنسية | E10: Required
A11: 4 | B11: Government ID type نوع الهوية | E11: Required
A12: 5 | B12: Government ID number رقم الهوية | E12: Required
A13: 6 | B13: Country of residence بلد الإقامة | E13: Required
A14: 7 | B14: Full residential address عنوان الإقامة الكامل | E14: Required
A15: B. Professional / المهنية
A16: 8 | B16: Primary domain القطاع الأساسي | E16: Required
A17: 9 | B17: Top 3 micro-specializations أبرز 3 تخصصات دقيقة | E17: Required
A18: 10 | B18: Years of experience سنوات الخبرة | E18: Required
A19: 11 | B19: Current employment status الحالة الوظيفية | E19: Required
A20: 12 | B20: Education (highest degree + institution + year) التعليم | E20: Required
A21: 13 | B21: Certifications (list) الشهادات المهنية | E21: Optional
A22: 14 | B22: Portfolio URL رابط الأعمال | E22: Required
A23: 15 | B23: LinkedIn لينكدإن | E23: Optional
A24: 16 | B24: GitHub / Behance / Dribbble روابط الأعمال | E24: Optional
A25: C. Verification (T1→T2) / التحقق
A26: 17 | B26: Government ID uploaded تحميل الهوية | E26: Required
A27: 18 | B27: Selfie with ID uploaded صورة ذاتية مع الهوية | E27: Required
A28: 19 | B28: Skill test passed? (score) نتيجة اختبار المهارة | E28: Required
A29: 20 | B29: Reference 1 name + contact المرجع 1 | E29: Optional
A30: 21 | B30: Reference 2 name + contact المرجع 2 | E30: Optional
A31: D. Finance / الشؤون المالية
A32: 22 | B32: Payment method طريقة الدفع | E32: Required
A33: 23 | B33: Payment currency العملة | E33: Required
A34: 24 | B34: Bank / wallet account holder name اسم صاحب الحساب | E34: Required
A35: 25 | B35: Account / IBAN / wallet handle رقم الحساب / المحفظة | E35: Required
A36: 26 | B36: Bank / wallet provider name اسم البنك / المحفظة | E36: Required
A37: 27 | B37: Tax resident country (for withholding) بلد الإقامة الضريبية | E37: Required
A38: E. Legal & consent / الإقرارات القانونية
A39: 28 | B39: NDA accepted اتفاقية عدم الإفصاح | E39: Required
A40: 29 | B40: IP assignment for paid work تنازل الملكية الفكرية | E40: Required
A41: 30 | B41: Kayan Code of Conduct accepted قبول ميثاق السلوك | E41: Required
A42: 31 | B42: 2170 escrow terms accepted قبول شروط الضمان 2170 | E42: Required
A43: 32 | B43: Data protection consent موافقة حماية البيانات | E43: Required
...

Sheet 10_REG_VOLUNTEER_FULL
A1: VOLUNTEER — FULL REGISTRATION (Day 1+) التسجيل الكامل للمتطوع (بعد الإطلاق)
A3: Sheet code: VLF · Version: v1.0 · Bilingual AR/EN · Mobile + WhatsApp compatible · Constitutional FX: 1 USD = 1,700 YER
A4: Completes safeguarding requirements and opens access to FAEAN missions. Background check runs within 7 days for youth-facing roles. يُكمل متطلبات الحماية ويفتح الوصول إلى مهام فعّان. يستغرق التحقق الأمني نحو 7 أيام للأدوار المتعلقة بالشباب.
A7: A. Identity / الهوية
A8: 1 | B8: Full legal name الاسم القانوني الكامل | E8: Required
A9: 2 | B9: Date of birth تاريخ الميلاد | E9: Required
A10: 3 | B10: Nationality الجنسية | E10: Required
A11: 4 | B11: Government ID type نوع الهوية | E11: Required
A12: 5 | B12: Government ID number رقم الهوية | E12: Required
A13: 6 | B13: Address العنوان | E13: Required
A14: B. Causes & skills / القضايا والمهارات
A15: 7 | B15: Top 3 causes أبرز 3 قضايا | E15: Required
A16: 8 | B16: Primary skill domain مجال المهارة الأساسي | E16: Required
A17: 9 | B17: Specific skills المهارات المحددة | E17: Required
A18: C. Availability / التوفر
A19: 10 | B19: Hours per month ساعات شهرياً | E19: Required
A20: 11 | B20: Start date تاريخ البدء | E20: Required
A21: 12 | B21: End date (if defined) تاريخ الانتهاء (إن وُجد) | E21: Optional
A22: 13 | B22: Mode (remote / on-site / both) نمط العمل | E22: Required
A23: D. Safeguarding / السلامة
A24: 14 | B24: Background check consent موافقة التحقق الأمني | E24: Required
A25: 15 | B25: Any criminal record? هل لديك سجل جنائي؟ | E25: Required
A26: 16 | B26: If yes, please describe وضح إذا كان الجواب نعم | E26: Optional
A27: 17 | B27: Emergency contact name اسم جهة الطوارئ | E27: Required
A28: 18 | B28: Emergency contact phone هاتف الطوارئ | E28: Required
A29: 19 | B29: Relation صلة القرابة | E29: Required
A30: E. Agreements / الإقرارات
A31: 20 | B31: Volunteer charter accepted ميثاق المتطوع | E31: Required
A32: 21 | B32: Code of conduct accepted ميثاق السلوك | E32: Required
A33: 22 | B33: Confidentiality acknowledged الإقرار بالسرية | E33: Required
A34: 23 | B34: Photo / media release السماح بالصور والإعلام | E34: Optional
A36: CONSENT & SUBMISSION META / الموافقة وبيانات الإرسال
A37: ☐ | B37: I consent to Kayan storing my data for EOI processing. أوافق على احتفاظ كيان ببياناتي لمعالجة اهتمامي. | E37: Required
A38: ☐ | B38: I agree to be contacted by Kayan through the channel I specified. أوافق على أن تتواصل كيان معي عبر القناة التي اخترتها. | E38: Required
A39: ☐ | B39: I confirm that all information provided is accurate to the best of my knowledge. أؤكد أن جميع المعلومات دقيقة حسب معرفتي. | E39: Required
A40: ☐ | B40: I am happy to receive updates (newsletter, events, opportunities). أرغب في تلقي التحديثات (النشرة والأحداث والفرص). | E40: Optional
A42: INTERNAL USE ONLY / لاستعمال الفريق فقط
B43: Submission ID (auto) معرّف الطلب | D43: ="KYN-VLF-"&TEXT(TODAY(),"YYYYMMDD")&"-"&TEXT(RANDBETWEEN(1000,9999),"0000") -> KYN-VLF-20260609-9301 | E43: Internal
B44: Received timestamp تاريخ الاستلام | D44: =NOW() -> 46182.775 | E44: Internal
B45: Intake channel قناة الاستلام | E45: Internal
...

Sheet 11_HUB_BOOKING
A1: HUB SPACE BOOKING نموذج حجز المساحة
A3: Sheet code: HBK · Version: v1.0 · Bilingual AR/EN · Mobile + WhatsApp compatible · Constitutional FX: 1 USD = 1,700 YER
A4: Individual booking form. For recurring / enterprise use, the Hub Membership contract supersedes this form. A confirmation with QR entry code is issued within 2 hours. نموذج الحجز الفردي. للاستخدام المتكرر أو المؤسسي يُستخدَم عقد العضوية بدلاً من هذا النموذج. يصل تأكيد الحجز مع رمز QR للدخول خلال ساعتين.
A7: A. Who is booking / بيانات الحجز
A8: 1 | B8: Booker full name اسم صاحب الحجز | E8: Required
A9: 2 | B9: Email البريد الإلكتروني | E9: Required
A10: 3 | B10: Mobile / WhatsApp الجوال / واتساب | E10: Required
A11: 4 | B11: Company (if any) الشركة (إن وُجدت) | E11: Optional
A12: 5 | B12: Existing member? عضو حالي؟ | E12: Required
A13: 6 | B13: Kayan member ID (if any) رقم العضوية (إن وُجد) | E13: Optional
A14: B. What to book / ما المطلوب
A15: 7 | B15: Booking type نوع الحجز | E15: Required
A16: 8 | B16: Number of seats / people عدد المقاعد أو الأشخاص | E16: Required
A17: 9 | B17: Date التاريخ | E17: Required
A18: 10 | B18: Start time وقت البدء | E18: Required
A19: 11 | B19: End time وقت الانتهاء | E19: Required
A20: 12 | B20: Recurring? (weekly / monthly) هل الحجز متكرر؟ | E20: Optional
A21: C. Pricing (calculated) / التسعير
A22: 13 | B22: Rate per unit (USD) السعر لكل وحدة ($) | E22: Required
A23: 14 | B23: Hours الساعات | E23: Required
A24: 15 | B24: Subtotal (USD) المجموع الفرعي ($) | E24: Optional
A25: D. Extras / الإضافات
A26: 16 | B26: F&B package? حزمة المقهى؟ | E26: Optional
A27: 17 | B27: Printing credits? حصة طباعة؟ | E27: Optional
A28: 18 | B28: A/V equipment? معدات صوت/صورة؟ | E28: Optional
A29: 19 | B29: Event coordinator on-site? منسق فعاليات بالموقع؟ | E29: Optional
A30: E. Payment / الدفع
A31: 20 | B31: Payment method طريقة الدفع | E31: Required
A32: 21 | B32: Currency العملة | E32: Required
A33: 22 | B33: Invoice needed? فاتورة مطلوبة؟ | E33: Required
A34: F. House rules / قواعد المكان
A35: 23 | B35: Accept hub house rules قبول قواعد المساحة | E35: Required
A36: 24 | B36: Cancellation policy acknowledged الإقرار بسياسة الإلغاء | E36: Required
A38: CONSENT & SUBMISSION META / الموافقة وبيانات الإرسال
A39: ☐ | B39: I consent to Kayan storing my data for EOI processing. أوافق على احتفاظ كيان ببياناتي لمعالجة اهتمامي. | E39: Required
A40: ☐ | B40: I agree to be contacted by Kayan through the channel I specified. أوافق على أن تتواصل كيان معي عبر القناة التي اخترتها. | E40: Required
A41: ☐ | B41: I confirm that all information provided is accurate to the best of my knowledge. أؤكد أن جميع المعلومات دقيقة حسب معرفتي. | E41: Required
A42: ☐ | B42: I am happy to receive updates (newsletter, events, opportunities). أرغب في تلقي التحديثات (النشرة والأحداث والفرص). | E42: Optional
A44: INTERNAL USE ONLY / لاستعمال الفريق فقط
B45: Submission ID (auto) معرّف الطلب | D45: ="KYN-HBK-"&TEXT(TODAY(),"YYYYMMDD")&"-"&TEXT(RANDBETWEEN(1000,9999),"0000") -> KYN-HBK-20260609-8613 | E45: Internal
...

Sheet 12_ACADEMY_ENROLL
A1: ACADEMY COHORT ENROLLMENT تسجيل دفعة الأكاديمية
A3: Sheet code: ACE · Version: v1.0 · Bilingual AR/EN · Mobile + WhatsApp compatible · Constitutional FX: 1 USD = 1,700 YER
A4: Once a cohort opens, this form confirms the learner's seat. Seat is released if first payment is not received within 5 business days. عند فتح الدفعة يؤكد هذا النموذج مقعد المتعلم. يُلغى المقعد إن لم تصل الدفعة الأولى خلال 5 أيام عمل.
A7: A. Learner / المتعلم
A8: 1 | B8: Full name الاسم الكامل | E8: Required
A9: 2 | B9: Age band الفئة العمرية | E9: Required
A10: 3 | B10: Email البريد الإلكتروني | E10: Required
A11: 4 | B11: Mobile / WhatsApp الجوال / واتساب | E11: Required
A12: 5 | B12: Country الدولة | E12: Required
A13: 6 | B13: City المدينة | E13: Required
A14: B. Course / الدورة
A15: 7 | B15: Course / track name اسم الدورة أو المسار | E15: Required
A16: 8 | B16: Cohort code / start date رمز الدفعة / تاريخ البدء | E16: Required
A17: 9 | B17: Format الصيغة | E17: Required
A18: 10 | B18: Duration (weeks) المدة (أسابيع) | E18: Required
A19: 11 | B19: Hours per week الساعات الأسبوعية | E19: Required
A20: C. Fee & payment / الرسوم والدفع
A21: 12 | B21: Full fee (USD) الرسوم الكاملة ($) | E21: Required
A22: 13 | B22: Scholarship applied (%) المنحة المطبقة (%) | E22: Optional
A23: 14 | B23: Amount due (USD) المبلغ المستحق ($) | E23: Required
A24: 15 | B24: Payment plan (installments) خطة الدفع | E24: Required
A25: 16 | B25: Currency العملة | E25: Required
A26: 17 | B26: First payment received? تم استلام الدفعة الأولى؟ | E26: Required
A27: D. Agreements / الإقرارات
A28: 18 | B28: Attendance policy accepted قبول سياسة الحضور | E28: Required
A29: 19 | B29: Refund policy acknowledged الإقرار بسياسة الاسترداد | E29: Required
A30: 20 | B30: Code of conduct accepted ميثاق السلوك | E30: Required
A31: 21 | B31: Consent to cohort group chat (WhatsApp) الموافقة على مجموعة الواتساب | E31: Optional
A33: CONSENT & SUBMISSION META / الموافقة وبيانات الإرسال
A34: ☐ | B34: I consent to Kayan storing my data for EOI processing. أوافق على احتفاظ كيان ببياناتي لمعالجة اهتمامي. | E34: Required
A35: ☐ | B35: I agree to be contacted by Kayan through the channel I specified. أوافق على أن تتواصل كيان معي عبر القناة التي اخترتها. | E35: Required
A36: ☐ | B36: I confirm that all information provided is accurate to the best of my knowledge. أؤكد أن جميع المعلومات دقيقة حسب معرفتي. | E36: Required
A37: ☐ | B37: I am happy to receive updates (newsletter, events, opportunities). أرغب في تلقي التحديثات (النشرة والأحداث والفرص). | E37: Optional
A39: INTERNAL USE ONLY / لاستعمال الفريق فقط
B40: Submission ID (auto) معرّف الطلب | D40: ="KYN-ACE-"&TEXT(TODAY(),"YYYYMMDD")&"-"&TEXT(RANDBETWEEN(1000,9999),"0000") -> KYN-ACE-20260609-5824 | E40: Internal
B41: Received timestamp تاريخ الاستلام | D41: =NOW() -> 46182.775 | E41: Internal
B42: Intake channel قناة الاستلام | E42: Internal
B43: Assigned handler الموظف المسؤول | E43: Internal
B44: Status الحالة | E44: Internal
B45: Next action + due date الإجراء التالي وتاريخه | E45: Internal
...

Sheet 13_SPECIALIZATIONS
A1: MICRO-SPECIALIZATIONS / التخصصات الدقيقة 60 disciplines across 8 domains
A3: Every talent, pod and SOW maps to a code here. Codes feed the matching engine and the Kayan Card.
A5: # | B5: Code | C5: Specialization (EN) | D5: التخصص (AR) | E5: Seniority tiers | F5: Typical deliverables
A6: 1 | B6: TECH-01 | C6: Frontend web engineering | D6: هندسة الواجهات الأمامية | E6: Jr / Mid / Sr / Lead | F6: Responsive UIs, Next.js apps
A7: 2 | B7: TECH-02 | C7: Backend API engineering | D7: هندسة الخلفيات وواجهات البرمجة | E7: Jr / Mid / Sr / Lead | F7: NestJS services, REST/GraphQL APIs
A8: 3 | B8: TECH-03 | C8: Mobile engineering (iOS/Android) | D8: هندسة تطبيقات الجوال | E8: Jr / Mid / Sr / Lead | F8: React Native / Flutter apps
A9: 4 | B9: TECH-04 | C9: DevOps & cloud | D9: التشغيل السحابي | E9: Jr / Mid / Sr / Lead | F9: CI/CD, Docker, Hetzner/Cloudflare
A10: 5 | B10: TECH-05 | C10: Data engineering | D10: هندسة البيانات | E10: Jr / Mid / Sr / Lead | F10: ETL, warehouses, BI pipelines
A11: 6 | B11: TECH-06 | C11: Data science & ML | D11: علوم البيانات وتعلم الآلة | E11: Jr / Mid / Sr / Lead | F11: Models, forecasting, scoring engines
A12: 7 | B12: TECH-07 | C12: QA / test engineering | D12: هندسة الجودة والاختبار | E12: Jr / Mid / Sr / Lead | F12: Test suites, automation, perf testing
A13: 8 | B13: TECH-08 | C13: Security engineering | D13: هندسة الأمن | E13: Mid / Sr / Lead | F13: Audits, pen-test, hardening
A14: 9 | B14: TECH-09 | C14: IT support & systems | D14: الدعم الفني والنظم | E14: Jr / Mid / Sr | F14: Setup, troubleshoot, networks
A15: 10 | B15: CRE-01 | C15: Brand & visual identity | D15: الهوية البصرية | E15: Jr / Mid / Sr / Lead | F15: Logo, brand book, systems
A16: 11 | B16: CRE-02 | C16: UI / UX design | D16: تصميم الواجهات والتجربة | E16: Jr / Mid / Sr / Lead | F16: Wireframes, prototypes, design systems
A17: 12 | B17: CRE-03 | C17: Graphic design | D17: التصميم الجرافيكي | E17: Jr / Mid / Sr | F17: Print, social, posters
... A65: 60 | B65: SPC-09 | C65: Impact measurement | D65: قياس الأثر | E65: Mid / Sr | F65: M&E frameworks, reporting

Sheet 14_WHATSAPP_SCRIPTS
A1: WHATSAPP INTAKE SCRIPTS / سكربتات واتساب للاستقبال
A3: Bilingual conversational flows. Each message ≤ 160 chars where possible. Bot sends → saves partial capture → human handler closes the loop within 24 hours.
A5: # | B5: Step | C5: English | D5: Arabic / العربية | E5: Type
B6: — CLIENT / العميل —
A7: 01 | B7: Welcome | C7: Ahlan 👋 This is Kayan — managed delivery + trusted pods. Reply START to share your project in 2 minutes. | D7: أهلاً 👋 هذه كيان — تنفيذ مُدار وفِرق موثوقة. أرسل ابدأ لنأخذ تفاصيل مشروعك في دقيقتين. | E7: bot
A8: 02 | B8: Name | C8: What is your full name? | D8: ما اسمك الكامل؟ | E8: capture
A9: 03 | B9: Company | C9: Company or organization name? | D9: اسم الشركة أو الجهة؟ | E9: capture
A10: 04 | B10: Industry | C10: Which industry? (e.g., retail, finance, health) | D10: ما القطاع؟ (مثلاً: تجارة، مالية، صحة) | E10: capture
A11: 05 | B11: Need | C11: In one sentence — what do you want to get done? | D11: في جملة — ما الذي تريد إنجازه؟ | E11: capture
A12: 06 | B12: Budget | C12: Budget band: <$500, $500-2k, $2k-10k, $10k-50k, $50k+, undecided? | D12: شريحة الميزانية: أقل من 500، 500-2000، 2000-10000، 10000-50000، 50000+، أو لم تحدد؟ | E12: capture
A13: 07 | B13: Deadline | C13: When do you need it done? (date or rough week) | D13: متى تحتاج الإنجاز؟ (تاريخ أو أسبوع تقريبي) | E13: capture
A14: 08 | B14: Email | C14: What email should we send the scoping call invite to? | D14: على أي بريد نرسل دعوة جلسة التحديد؟ | E14: capture
A15: 09 | B15: Close | C15: Thank you. A handler will reach you within 24 hours with a scoping call. Reply STOP to pause. | D15: شكراً لك. سيتواصل معك أحد الفريق خلال 24 ساعة لتحديد جلسة العمل. أرسل إيقاف لإيقاف المحادثة. | E15: bot
B16: — TALENT / المستقل —
A17: 01 | B17: Welcome | C17: Ahlan, talent 👋 This is Kayan. We match verified talent to paid, escrow-protected work. Reply START to join the waitlist in 90 seconds. | D17: أهلاً أيها المستقل 👋 كيان تربط الموهبة الموثقة بعمل مدفوع محمي بضمان. أرسل ابدأ للانضمام إلى قائمة الانتظار في 90 ثانية. | E17: bot
A18: 02 | B18: Name | C18: Full name? | D18: الاسم الكامل؟ | E18: capture
A19: 03 | B19: Domain | C19: Primary domain: 1-Tech 2-Creative 3-Business 4-Training 5-Research 6-Consulting 7-Field 8-Specialist | D19: المجال الأساسي: 1-تقني 2-إبداعي 3-أعمال 4-تدريب 5-بحث 6-استشارات 7-ميداني 8-متخصص | E19: capture
A20: 04 | B20: MicroSpec | C20: Your top skill (1-2 words) | D20: مهارتك الأبرز (كلمة أو اثنتان) | E20: capture
A21: 05 | B21: Years | C21: Years of experience? | D21: سنوات الخبرة؟ | E21: capture
A22: 06 | B22: Rate | C22: Your hourly rate in USD (or YER)? | D22: سعرك بالساعة بالدولار (أو بالريال)؟ | E22: capture
A23: 07 | B23: Portfolio | C23: Portfolio / LinkedIn URL (skip if none) | D23: رابط أعمالك أو لينكدإن (تجاوز إن لم يوجد) | E23: capture
A24: 08 | B24: City | C24: City of residence? | D24: مدينة الإقامة؟ | E24: capture
A25: 09 | B25: Email | C25: Email for verification? | D25: بريدك للتحقق؟ | E25: capture
A26: 10 | B26: Close | C26: Saved ✦ A verifier will reach you within 48 hours. Pass the skill test and we issue your Kayan Card (T2). | D26: تم الحفظ ✦ سيتواصل معك مسؤول التحقق خلال 48 ساعة. بعد اجتياز الاختبار نُصدر لك بطاقة كيان (T2). | E26: bot
B27: — VOLUNTEER / المتطوع —
A28: 01 | B28: Welcome | C28: Ahlan 👋 FAEAN (by Kayan) — volunteers matched to causes where their skill lands. Reply START to join. | D28: أهلاً 👋 فعّان (من كيان) — متطوعون يُطابقون بمهاراتهم على القضايا. أرسل ابدأ للانضمام. | E28: bot
A29: 02 | B29: Name | C29: Full name? | D29: الاسم الكامل؟ | E29: capture
A30: 03 | B30: City | C30: City? | D30: المدينة؟ | E30: capture
A31: 04 | B31: Causes | C31: Top 3 causes (education, youth, women, health, env, community, humanitarian) | D31: أهم 3 قضايا (تعليم، شباب، مرأة، صحة، بيئة، مجتمع، إنساني) | E31: capture
A32: 05 | B32: Skill | C32: Your main skill you can offer? | D32: مهارتك الرئيسية التي يمكن تقديمها؟ | E32: capture
A33: 06 | B33: Hours | C33: Hours per month you can give? | D33: ساعات شهرياً يمكنك التبرع بها؟ | E33: capture
A34: 07 | B34: Start | C34: When can you start? | D34: متى يمكنك البدء؟ | E34: capture
A35: 08 | B35: Email | C35: Email for coordination? | D35: بريد للتنسيق؟ | E35: capture
A36: 09 | B36: Close | C36: Thank you ✦ A FAEAN coordinator will reach you within 48 hours. | D36: شكراً ✦ سيتواصل معك منسق فعّان خلال 48 ساعة. | E36: bot
B37: — HUB / المساحة —
A38: 01 | B38: Welcome | C38: Ahlan 👋 Kayan Hub — quiet, beautiful, where work gets done. Reply START to tell us what you need. | D38: أهلاً 👋 مساحة كيان — هادئة وجميلة، حيث يُنجَز العمل. أرسل ابدأ لنعرف ما تحتاج. | E38: bot
A39: 02 | B39: Use | C39: What do you need? (hot desk / private office / meeting room / event) | D39: ماذا تحتاج؟ (مكتب مفتوح / مكتب خاص / قاعة اجتماعات / فعالية) | E39: capture
A40: 03 | B40: People | C40: Number of people? | D40: عدد الأشخاص؟ | E40: capture
A41: 04 | B41: When | C41: Date and time? | D41: التاريخ والوقت؟ | E41: capture
A42: 05 | B42: Freq | C42: One-off or recurring? | D42: مرة واحدة أم متكرر؟ | E42: capture
...

Sheet 15_RESPONSE_TEMPLATES
A1: AUTO-REPLY TEMPLATES / قوالب الرد التلقائي
A3: Used by email + WhatsApp + SMS bots. Placeholders in {curly braces} come from the captured form data.
A5: # | B5: Template code | C5: Channel | D5: English body | E5: Arabic / العربية
A6: 1 | B6: T-ACK-CLIENT | C6: Email + WA | D6: Hi {name}, thank you for your interest in Kayan. We received your brief for {company}. A handler will contact you within 24h to schedule a scoping call. — Kayan | E6: مرحباً {name}، شكراً لاهتمامك بكيان. استلمنا بياناتك عن {company}. سيتواصل معك أحد الفريق خلال 24 ساعة لتحديد موعد جلسة العمل. — كيان
A7: 2 | B7: T-ACK-TALENT | C7: Email + WA | D7: Hi {name}, thanks for joining the Kayan talent waitlist. Expect a verification call within 48h. Pass the skill test and we issue your Kayan Card (T2). — Kayan Talent Desk | E7: مرحباً {name}، شكراً لانضمامك إلى قائمة انتظار مواهب كيان. سيصلك اتصال تحقق خلال 48 ساعة. بعد اختبار المهارة نُصدر بطاقة كيان (T2). — مكتب المواهب
A8: 3 | B8: T-ACK-VOL | C8: Email + WA | D8: Salam {name}, welcome to FAEAN. We match volunteers to missions where their skill counts. A coordinator reaches you within 48h. — FAEAN by Kayan | E8: السلام عليكم {name}، أهلاً بك في فعّان. نطابقك مع مهمة تفيد فيها مهارتك. سيتواصل معك المنسق خلال 48 ساعة. — فعّان من كيان
A9: 4 | B9: T-ACK-HUB | C9: Email + WA | D9: Hi {name}, your hub enquiry is noted. We hold your preferred setup and reply within 2h with a quote and reservation link. — Kayan Hub | E9: مرحباً {name}، تم تسجيل استفسارك عن المساحة. نحجز إعدادك المفضل ونرد خلال ساعتين بعرض سعر ورابط الحجز. — مساحة كيان
A10: 5 | B10: T-ACK-ACADEMY | C10: Email + WA | D10: Hi {name}, you are on the Kayan Academy cohort waitlist for {track}. We will invite you to the next cohort briefing. | E10: مرحباً {name}، تم إدراجك في قائمة دفعة أكاديمية كيان لمسار {track}. سندعوك للجلسة التعريفية القادمة.
A11: 6 | B11: T-ACK-BUSINESS | C11: Email + WA | D11: Hello {name}, thank you. A Kayan relationship lead will reach you within 48h with a tailored package for {company}. | E11: مرحباً {name}، شكراً لك. سيتواصل معك مدير العلاقات في كيان خلال 48 ساعة بعرض مخصص لـ{company}.
A12: 7 | B12: T-FOLLOWUP-D3 | C12: Email | D12: Gentle follow-up to your EOI — reminder we are still here and would love to connect. Reply with a time window that works for you. | E12: متابعة لنموذج اهتمامك — لا زلنا في الخدمة ونود التواصل. أرسل لنا وقتاً مناسباً.
A13: 8 | B13: T-FOLLOWUP-D7 | C13: Email | D13: Just checking in — does the timing still make sense? We will park your file for 90 days unless we hear back. | E13: متابعة — هل ما زال التوقيت مناسباً؟ سنحتفظ بملفك لمدة 90 يوماً ما لم نسمع منك.
A14: 9 | B14: T-SCHEDULE | C14: Email | D14: Scoping call scheduled for {date} at {time} ({timezone}). Location: {location}. Agenda attached. — Kayan | E14: تم تحديد جلسة العمل في {date} الساعة {time} ({timezone}). المكان: {location}. جدول الأعمال مرفق. — كيان
A15: 10 | B15: T-SOW-READY | C15: Email | D15: Your SOW ({sow_id}) is ready for review. Please open the link, review, and sign if you are happy. Escrow funding instructions follow signature. | E15: نطاق العمل {sow_id} جاهز للمراجعة. افتح الرابط وراجعه ووقّعه إن وافقت. تعليمات تمويل الضمان تتبع التوقيع.
A16: 11 | B16: T-DECLINE-POLITE | C16: Email + WA | D16: Thank you — we are not able to take this on right now, but we will keep your brief on file for 18 months. We are grateful you considered us. | E16: شكراً لك — لا يمكننا تولي هذا الأمر حالياً، لكننا سنحتفظ ببياناتك لمدة 18 شهراً. نُقدّر ثقتك.
A17: 12 | B17: T-OOH | C17: WA | D17: Outside office hours — we reply Sun-Thu 8:30-17:00 (AST). Leave your message and we will respond first thing. | E17: خارج ساعات العمل — نرد من الأحد إلى الخميس 8:30-17:00 (بتوقيت عدن). اترك رسالتك ونرد في أول فرصة.

Sheet 16_AUDIT_LOG
A1: AUDIT LOG — EOI SUBMISSIONS / سجل التدقيق
A3: Append-only log. One row per submission. Production system replaces this with the immutable Postgres audit table + SHA-256 chain hash — this sheet is the manual mirror for the pre-launch period.
A5: # | B5: Submission ID | C5: Form | D5: Channel | E5: Received (UTC) | F5: Name | G5: Country | H5: Email / Phone | I5: Status | J5: Handler
A6: 1 | B6: KYN-CL-20260419-0001 | C6: 02_EOI_CLIENT | D6: Web | E6: 2026-04-19 10:14 | F6: {auto} | G6: Yemen | H6: client@example.com | I6: Received | J6: —
A7: 2 | B7: KYN-TL-20260419-0002 | C7: 03_EOI_FREELANCER | D7: WhatsApp | E7: 2026-04-19 10:22 | F7: {auto} | G7: Egypt | H7: +20 xx xxxx xxxx | I7: Received | J7: —
A8: 3 | B8: KYN-VL-20260419-0003 | C8: 05_EOI_VOLUNTEER | D8: Referral | E8: 2026-04-19 10:41 | F8: {auto} | G8: Yemen | H8: vol@example.com | I8: Contacted | J8: Amal

Sheet 17_KPI_DASH
A1: PRE-LAUNCH KPI DASHBOARD / لوحة مؤشرات الإطلاق
A3: Dashboard auto-updates from 16_AUDIT_LOG. Refresh weekly. Targets below reflect the 25 Apr → 31 May 2026 window (Tech OS v8.0 §5).
A5: # | B5: KPI | C5: Target | D5: Actual | E5: Gap | F5: % complete | G5: Status | H5: Owner
A6: 1 | B6: Client EOIs received | C6: 30 | D6: =COUNTIF('16_AUDIT_LOG'!C:C,"02_EOI_CLIENT") -> 1 | E6: =MAX(0,C6-D6) -> 29 | F6: =IFERROR(D6/C6,0) -> 0.033333333 | G6: =IF(F6>=1,"✦ Met",IF(F6>=0.7,"On track",IF(F6>=0.3,"Behind","At risk"))) -> At risk | H6: Maher / Sales
A7: 2 | B7: Talent EOIs received | C7: 150 | D7: =COUNTIF('16_AUDIT_LOG'!C:C,"03_EOI_FREELANCER") -> 1 | E7: =MAX(0,C7-D7) -> 149 | F7: =IFERROR(D7/C7,0) -> 0.0066666667 | G7: =IF(F7>=1,"✦ Met",IF(F7>=0.7,"On track",IF(F7>=0.3,"Behind","At risk"))) -> At risk | H7: Talent Desk
A8: 3 | B8: Business / partner EOIs | C8: 40 | D8: =COUNTIF('16_AUDIT_LOG'!C:C,"04_EOI_BUSINESS") -> 0 | E8: =MAX(0,C8-D8) -> 40 | F8: =IFERROR(D8/C8,0) -> 0 | G8: =IF(F8>=1,"✦ Met",IF(F8>=0.7,"On track",IF(F8>=0.3,"Behind","At risk"))) -> At risk | H8: Maher
A9: 4 | B9: Volunteer EOIs (FAEAN) | C9: 50 | D9: =COUNTIF('16_AUDIT_LOG'!C:C,"05_EOI_VOLUNTEER") -> 1 | E9: =MAX(0,C9-D9) -> 49 | F9: =IFERROR(D9/C9,0) -> 0.02 | G9: =IF(F9>=1,"✦ Met",IF(F9>=0.7,"On track",IF(F9>=0.3,"Behind","At risk"))) -> At risk | H9: FAEAN Coordinator
A10: 5 | B10: Academy learner EOIs | C10: 40 | D10: =COUNTIF('16_AUDIT_LOG'!C:C,"06_EOI_ACADEMY") -> 0 | E10: =MAX(0,C10-D10) -> 40 | F10: =IFERROR(D10/C10,0) -> 0 | G10: =IF(F10>=1,"✦ Met",IF(F10>=0.7,"On track",IF(F10>=0.3,"Behind","At risk"))) -> At risk | H10: Academy Lead
A11: 6 | B11: Hub enquiries | C11: 20 | D11: =COUNTIF('16_AUDIT_LOG'!C:C,"07_EOI_HUB") -> 0 | E11: =MAX(0,C11-D11) -> 20 | F11: =IFERROR(D11/C11,0) -> 0 | G11: =IF(F11>=1,"✦ Met",IF(F11>=0.7,"On track",IF(F11>=0.3,"Behind","At risk"))) -> At risk | H11: Hub Manager
A12: 7 | B12: T2 verified talent | C12: 50 | D12: =COUNTIF('16_AUDIT_LOG'!C:C,"09_REG_TALENT_FULL") -> 0 | E12: =MAX(0,C12-D12) -> 50 | F12: =IFERROR(D12/C12,0) -> 0 | G12: =IF(F12>=1,"✦ Met",IF(F12>=0.7,"On track",IF(F12>=0.3,"Behind","At risk"))) -> At risk | H12: Talent Desk
A13: 8 | B13: Full client registrations | C13: 10 | D13: =COUNTIF('16_AUDIT_LOG'!C:C,"08_REG_CLIENT_FULL") -> 0 | E13: =MAX(0,C13-D13) -> 10 | F13: =IFERROR(D13/C13,0) -> 0 | G13: =IF(F13>=1,"✦ Met",IF(F13>=0.7,"On track",IF(F13>=0.3,"Behind","At risk"))) -> At risk | H13: Maher
A14: 9 | B14: Hub anchor bookings | C14: 8 | D14: =COUNTIF('16_AUDIT_LOG'!C:C,"11_HUB_BOOKING") -> 0 | E14: =MAX(0,C14-D14) -> 8 | F14: =IFERROR(D14/C14,0) -> 0 | G14: =IF(F14>=1,"✦ Met",IF(F14>=0.7,"On track",IF(F14>=0.3,"Behind","At risk"))) -> At risk | H14: Hub Manager
A15: 10 | B15: Academy cohort confirmed | C15: 1 | D15: =COUNTIF('16_AUDIT_LOG'!C:C,"12_ACADEMY_ENROLL") -> 0 | E15: =MAX(0,C15-D15) -> 1 | F15: =IFERROR(D15/C15,0) -> 0 | G15: =IF(F15>=1,"✦ Met",IF(F15>=0.7,"On track",IF(F15>=0.3,"Behind","At risk"))) -> At risk | H15: Academy Lead
A18: AGGREGATE ROLL-UP / ملخص كلي
B19: Total target EOIs (all forms) | C19: =SUM(C6:C15) -> 399 | D19: =SUM(D6:D15) -> 3 | F19: =IFERROR(D19/C19,0) -> 0.007518797
